<sdf version='1.6'>
  <world name='default'>
    <physics name='default_physics' default='0' type='ode'>
      <ode>
        <solver>
          <type>quick</type>
          <iters>100</iters>
          <sor>1</sor>
          <use_dynamic_moi_rescaling>0</use_dynamic_moi_rescaling>
        </solver>
        <constraints>
          <cfm>0</cfm>
          <erp>0.9</erp>
          <contact_max_correcting_vel>0.1</contact_max_correcting_vel>
          <contact_surface_layer>0</contact_surface_layer>
        </constraints>
      </ode>
      <real_time_update_rate>-1</real_time_update_rate>
      <max_step_size>0.001</max_step_size>
      <real_time_factor>1</real_time_factor>
    </physics>
    <model name='ground_plane'>
      <static>1</static>
      <link name='link'>
        <collision name='collision'>
          <geometry>
            <plane>
              <normal>0 0 1</normal>
              <size>5000 5000</size>
            </plane>
          </geometry>
          <surface>
            <friction>
              <ode>
                <mu>1</mu>
                <mu2>1</mu2>
              </ode>
              <torsional>
                <ode/>
              </torsional>
            </friction>
            <contact>
              <ode/>
            </contact>
            <bounce/>
          </surface>
          <max_contacts>10</max_contacts>
        </collision>
        <self_collide>0</self_collide>
        <enable_wind>0</enable_wind>
        <kinematic>0</kinematic>
      </link>
    </model>
    <light name='sun' type='directional'>
      <cast_shadows>1</cast_shadows>
      <pose frame=''>0 0 10 0 -0 0</pose>
      <diffuse>0.8 0.8 0.8 1</diffuse>
      <specular>0.2 0.2 0.2 1</specular>
      <attenuation>
        <range>1000</range>
        <constant>0.9</constant>
        <linear>0.01</linear>
        <quadratic>0.001</quadratic>
      </attenuation>
      <direction>-0.5 0.1 -0.9</direction>
    </light>
    <model name='iris'>
      <link name='iris_demo::iris::base_link'>
        <velocity_decay>
          <linear>0</linear>
          <angular>0</angular>
        </velocity_decay>
        <inertial>
          <pose frame=''>0 0 0 0 -0 0</pose>
          <mass>1.5</mass>
          <inertia>
            <ixx>0.008</ixx>
            <ixy>0</ixy>
            <ixz>0</ixz>
            <iyy>0.015</iyy>
            <iyz>0</iyz>
            <izz>0.017</izz>
          </inertia>
        </inertial>
        <collision name='base_link_collision'>
          <pose frame=''>0 0 -0.08 0 -0 0</pose>
          <geometry>
            <box>
              <size>0.47 0.47 0.23</size>
            </box>
          </geometry>
          <surface>
            <contact>
              <ode>
                <max_vel>100</max_vel>
                <min_depth>0.001</min_depth>
              </ode>
            </contact>
            <friction>
              <ode>
                <mu>100000</mu>
                <mu2>100000</mu2>
              </ode>
              <torsional>
                <ode/>
              </torsional>
            </friction>
            <bounce/>
          </surface>
          <max_contacts>10</max_contacts>
        </collision>
        <visual name='base_link_visual'>
          <geometry>
            <mesh>
              <uri>model://iris_with_standoffs/meshes/iris.dae</uri>
            </mesh>
          </geometry>
          <material>
            <script>
              <name>Gazebo/DarkGrey</name>
              <uri>__default__</uri>
            </script>
          </material>
        </visual>
        <visual name='front_left_leg_visual'>
          <pose frame=''>0.123 0.22 -0.11 0 -0 0</pose>
          <geometry>
            <cylinder>
              <radius>0.005</radius>
              <length>0.17</length>
            </cylinder>
          </geometry>
          <material>
            <script>
              <name>Gazebo/FlatBlack</name>
              <uri>file://media/materials/scripts/gazebo.material</uri>
            </script>
          </material>
        </visual>
        <visual name='front_right_leg_visual'>
          <pose frame=''>0.123 -0.22 -0.11 0 -0 0</pose>
          <geometry>
            <cylinder>
              <radius>0.005</radius>
              <length>0.17</length>
            </cylinder>
          </geometry>
          <material>
            <script>
              <name>Gazebo/FlatBlack</name>
              <uri>file://media/materials/scripts/gazebo.material</uri>
            </script>
          </material>
        </visual>
        <visual name='rear_left_leg_visual'>
          <pose frame=''>-0.14 0.21 -0.11 0 -0 0</pose>
          <geometry>
            <cylinder>
              <radius>0.005</radius>
              <length>0.17</length>
            </cylinder>
          </geometry>
          <material>
            <script>
              <name>Gazebo/FlatBlack</name>
              <uri>file://media/materials/scripts/gazebo.material</uri>
            </script>
          </material>
        </visual>
        <visual name='rear_right_leg_visual'>
          <pose frame=''>-0.14 -0.21 -0.11 0 -0 0</pose>
          <geometry>
            <cylinder>
              <radius>0.005</radius>
              <length>0.17</length>
            </cylinder>
          </geometry>
          <material>
            <script>
              <name>Gazebo/FlatBlack</name>
              <uri>file://media/materials/scripts/gazebo.material</uri>
            </script>
          </material>
        </visual>
        <pose frame=''>0 0 0.194923 0 -0 0</pose>
        <self_collide>0</self_collide>
        <enable_wind>0</enable_wind>
        <kinematic>0</kinematic>
      </link>
      <link name='iris_demo::iris::iris/ground_truth/odometry_sensorgt_link'>
        <pose frame=''>0 0 0.194923 0 -0 0</pose>
        <inertial>
          <pose frame=''>0 0 0 0 -0 0</pose>
          <mass>0.15</mass>
          <inertia>
            <ixx>0.0001</ixx>
            <ixy>0</ixy>
            <ixz>0</ixz>
            <iyy>0.0002</iyy>
            <iyz>0</iyz>
            <izz>0.0002</izz>
          </inertia>
        </inertial>
        <self_collide>0</self_collide>
        <enable_wind>0</enable_wind>
        <kinematic>0</kinematic>
      </link>
      <joint name='iris_demo::iris::iris/ground_truth/odometry_sensorgt_joint' type='revolute'>
        <child>iris_demo::iris::iris/ground_truth/odometry_sensorgt_link</child>
        <parent>iris_demo::iris::base_link</parent>
        <axis>
          <xyz>0 0 1</xyz>
          <limit>
            <lower>0</lower>
            <upper>0</upper>
            <effort>0</effort>
            <velocity>0</velocity>
          </limit>
          <dynamics>
            <damping>1</damping>
            <spring_reference>0</spring_reference>
            <spring_stiffness>0</spring_stiffness>
          </dynamics>
          <use_parent_model_frame>1</use_parent_model_frame>
        </axis>
        <physics>
          <ode>
            <implicit_spring_damper>1</implicit_spring_damper>
            <limit>
              <cfm>0</cfm>
              <erp>0.2</erp>
            </limit>
          </ode>
        </physics>
      </joint>
      <link name='iris_demo::iris::iris/imu_link'>
        <inertial>
          <pose frame=''>0 0 0 0 -0 0</pose>
          <mass>0.15</mass>
          <inertia>
            <ixx>1e-05</ixx>
            <ixy>0</ixy>
            <ixz>0</ixz>
            <iyy>2e-05</iyy>
            <iyz>0</iyz>
            <izz>2e-05</izz>
          </inertia>
        </inertial>
        <sensor name='imu_sensor' type='imu'>
          <pose frame=''>0 0 0 -3.14159 -0 0</pose>
          <always_on>1</always_on>
          <update_rate>1000</update_rate>
          <imu/>
        </sensor>
        <pose frame=''>0 0 0.194923 0 -0 0</pose>
        <self_collide>0</self_collide>
        <enable_wind>0</enable_wind>
        <kinematic>0</kinematic>
      </link>
      <joint name='iris_demo::iris::iris/imu_joint' type='revolute'>
        <child>iris_demo::iris::iris/imu_link</child>
        <parent>iris_demo::iris::base_link</parent>
        <axis>
          <xyz>0 0 1</xyz>
          <limit>
            <lower>0</lower>
            <upper>0</upper>
            <effort>0</effort>
            <velocity>0</velocity>
          </limit>
          <dynamics>
            <damping>1</damping>
            <spring_reference>0</spring_reference>
            <spring_stiffness>0</spring_stiffness>
          </dynamics>
          <use_parent_model_frame>1</use_parent_model_frame>
        </axis>
        <physics>
          <ode>
            <implicit_spring_damper>1</implicit_spring_damper>
            <limit>
              <cfm>0</cfm>
              <erp>0.2</erp>
            </limit>
          </ode>
        </physics>
      </joint>
      <link name='iris_demo::iris::rotor_0'>
        <pose frame=''>0.13 -0.22 0.217923 0 -0 0</pose>
        <inertial>
          <pose frame=''>0 0 0 0 -0 0</pose>
          <mass>0.025</mass>
          <inertia>
            <ixx>9.75e-06</ixx>
            <ixy>0</ixy>
            <ixz>0</ixz>
            <iyy>0.000166704</iyy>
            <iyz>0</iyz>
            <izz>0.000167604</izz>
          </inertia>
        </inertial>
        <collision name='rotor_0_collision'>
          <pose frame=''>0 0 0 0 -0 0</pose>
          <geometry>
            <cylinder>
              <length>0.005</length>
              <radius>0.1</radius>
            </cylinder>
          </geometry>
          <surface>
            <contact>
              <ode/>
            </contact>
            <friction>
              <ode/>
              <torsional>
                <ode/>
              </torsional>
            </friction>
            <bounce/>
          </surface>
          <max_contacts>10</max_contacts>
        </collision>
        <visual name='rotor_0_visual'>
          <pose frame=''>0 0 0 0 -0 0</pose>
          <geometry>
            <mesh>
              <scale>1 1 1</scale>
              <uri>model://iris_with_standoffs/meshes/iris_prop_ccw.dae</uri>
            </mesh>
          </geometry>
          <material>
            <script>
              <name>Gazebo/Blue</name>
              <uri>__default__</uri>
            </script>
          </material>
        </visual>
        <gravity>1</gravity>
        <velocity_decay/>
        <self_collide>0</self_collide>
        <enable_wind>0</enable_wind>
        <kinematic>0</kinematic>
      </link>
      <joint name='iris_demo::iris::rotor_0_joint' type='revolute'>
        <child>iris_demo::iris::rotor_0</child>
        <parent>iris_demo::iris::base_link</parent>
        <axis>
          <xyz>0 0 1</xyz>
          <limit>
            <lower>-1e+16</lower>
            <upper>1e+16</upper>
          </limit>
          <dynamics>
            <damping>0.004</damping>
            <spring_reference>0</spring_reference>
            <spring_stiffness>0</spring_stiffness>
          </dynamics>
          <use_parent_model_frame>1</use_parent_model_frame>
        </axis>
        <physics>
          <ode>
            <implicit_spring_damper>1</implicit_spring_damper>
            <limit>
              <cfm>0</cfm>
              <erp>0.2</erp>
            </limit>
          </ode>
        </physics>
      </joint>
      <link name='iris_demo::iris::rotor_1'>
        <pose frame=''>-0.13 0.2 0.217923 0 -0 0</pose>
        <inertial>
          <pose frame=''>0 0 0 0 -0 0</pose>
          <mass>0.025</mass>
          <inertia>
            <ixx>9.75e-06</ixx>
            <ixy>0</ixy>
            <ixz>0</ixz>
            <iyy>0.000166704</iyy>
            <iyz>0</iyz>
            <izz>0.000167604</izz>
          </inertia>
        </inertial>
        <collision name='rotor_1_collision'>
          <pose frame=''>0 0 0 0 -0 0</pose>
          <geometry>
            <cylinder>
              <length>0.005</length>
              <radius>0.1</radius>
            </cylinder>
          </geometry>
          <surface>
            <contact>
              <ode/>
            </contact>
            <friction>
              <ode/>
              <torsional>
                <ode/>
              </torsional>
            </friction>
            <bounce/>
          </surface>
          <max_contacts>10</max_contacts>
        </collision>
        <visual name='rotor_1_visual'>
          <pose frame=''>0 0 0 0 -0 0</pose>
          <geometry>
            <mesh>
              <scale>1 1 1</scale>
              <uri>model://iris_with_standoffs/meshes/iris_prop_ccw.dae</uri>
            </mesh>
          </geometry>
          <material>
            <script>
              <name>Gazebo/DarkGrey</name>
              <uri>__default__</uri>
            </script>
          </material>
        </visual>
        <gravity>1</gravity>
        <velocity_decay/>
        <self_collide>0</self_collide>
        <enable_wind>0</enable_wind>
        <kinematic>0</kinematic>
      </link>
      <joint name='iris_demo::iris::rotor_1_joint' type='revolute'>
        <child>iris_demo::iris::rotor_1</child>
        <parent>iris_demo::iris::base_link</parent>
        <axis>
          <xyz>0 0 1</xyz>
          <limit>
            <lower>-1e+16</lower>
            <upper>1e+16</upper>
          </limit>
          <dynamics>
            <damping>0.004</damping>
            <spring_reference>0</spring_reference>
            <spring_stiffness>0</spring_stiffness>
          </dynamics>
          <use_parent_model_frame>1</use_parent_model_frame>
        </axis>
        <physics>
          <ode>
            <implicit_spring_damper>1</implicit_spring_damper>
            <limit>
              <cfm>0</cfm>
              <erp>0.2</erp>
            </limit>
          </ode>
        </physics>
      </joint>
      <link name='iris_demo::iris::rotor_2'>
        <pose frame=''>0.13 0.22 0.217923 0 -0 0</pose>
        <inertial>
          <pose frame=''>0 0 0 0 -0 0</pose>
          <mass>0.025</mass>
          <inertia>
            <ixx>9.75e-06</ixx>
            <ixy>0</ixy>
            <ixz>0</ixz>
            <iyy>0.000166704</iyy>
            <iyz>0</iyz>
            <izz>0.000167604</izz>
          </inertia>
        </inertial>
        <collision name='rotor_2_collision'>
          <pose frame=''>0 0 0 0 -0 0</pose>
          <geometry>
            <cylinder>
              <length>0.005</length>
              <radius>0.1</radius>
            </cylinder>
          </geometry>
          <surface>
            <contact>
              <ode/>
            </contact>
            <friction>
              <ode/>
              <torsional>
                <ode/>
              </torsional>
            </friction>
            <bounce/>
          </surface>
          <max_contacts>10</max_contacts>
        </collision>
        <visual name='rotor_2_visual'>
          <pose frame=''>0 0 0 0 -0 0</pose>
          <geometry>
            <mesh>
              <scale>1 1 1</scale>
              <uri>model://iris_with_standoffs/meshes/iris_prop_cw.dae</uri>
            </mesh>
          </geometry>
          <material>
            <script>
              <name>Gazebo/Blue</name>
              <uri>__default__</uri>
            </script>
          </material>
        </visual>
        <gravity>1</gravity>
        <velocity_decay/>
        <self_collide>0</self_collide>
        <enable_wind>0</enable_wind>
        <kinematic>0</kinematic>
      </link>
      <joint name='iris_demo::iris::rotor_2_joint' type='revolute'>
        <child>iris_demo::iris::rotor_2</child>
        <parent>iris_demo::iris::base_link</parent>
        <axis>
          <xyz>0 0 1</xyz>
          <limit>
            <lower>-1e+16</lower>
            <upper>1e+16</upper>
          </limit>
          <dynamics>
            <damping>0.004</damping>
            <spring_reference>0</spring_reference>
            <spring_stiffness>0</spring_stiffness>
          </dynamics>
          <use_parent_model_frame>1</use_parent_model_frame>
        </axis>
        <physics>
          <ode>
            <implicit_spring_damper>1</implicit_spring_damper>
            <limit>
              <cfm>0</cfm>
              <erp>0.2</erp>
            </limit>
          </ode>
        </physics>
      </joint>
      <link name='iris_demo::iris::rotor_3'>
        <pose frame=''>-0.13 -0.2 0.217923 0 -0 0</pose>
        <inertial>
          <pose frame=''>0 0 0 0 -0 0</pose>
          <mass>0.025</mass>
          <inertia>
            <ixx>9.75e-06</ixx>
            <ixy>0</ixy>
            <ixz>0</ixz>
            <iyy>0.000166704</iyy>
            <iyz>0</iyz>
            <izz>0.000167604</izz>
          </inertia>
        </inertial>
        <collision name='rotor_3_collision'>
          <pose frame=''>0 0 0 0 -0 0</pose>
          <geometry>
            <cylinder>
              <length>0.005</length>
              <radius>0.1</radius>
            </cylinder>
          </geometry>
          <surface>
            <contact>
              <ode/>
            </contact>
            <friction>
              <ode/>
              <torsional>
                <ode/>
              </torsional>
            </friction>
            <bounce/>
          </surface>
          <max_contacts>10</max_contacts>
        </collision>
        <visual name='rotor_3_visual'>
          <pose frame=''>0 0 0 0 -0 0</pose>
          <geometry>
            <mesh>
              <scale>1 1 1</scale>
              <uri>model://iris_with_standoffs/meshes/iris_prop_cw.dae</uri>
            </mesh>
          </geometry>
          <material>
            <script>
              <name>Gazebo/DarkGrey</name>
              <uri>__default__</uri>
            </script>
          </material>
        </visual>
        <gravity>1</gravity>
        <velocity_decay/>
        <self_collide>0</self_collide>
        <enable_wind>0</enable_wind>
        <kinematic>0</kinematic>
      </link>
      <joint name='iris_demo::iris::rotor_3_joint' type='revolute'>
        <child>iris_demo::iris::rotor_3</child>
        <parent>iris_demo::iris::base_link</parent>
        <axis>
          <xyz>0 0 1</xyz>
          <limit>
            <lower>-1e+16</lower>
            <upper>1e+16</upper>
          </limit>
          <dynamics>
            <damping>0.004</damping>
            <spring_reference>0</spring_reference>
            <spring_stiffness>0</spring_stiffness>
          </dynamics>
          <use_parent_model_frame>1</use_parent_model_frame>
        </axis>
        <physics>
          <ode>
            <implicit_spring_damper>1</implicit_spring_damper>
            <limit>
              <cfm>0</cfm>
              <erp>0.2</erp>
            </limit>
          </ode>
        </physics>
      </joint>
      <static>0</static>
      <link name='iris_demo::gimbal_small_2d::base_link'>
        <inertial>
          <mass>0.2</mass>
          <inertia>
            <ixx>0.0001</ixx>
            <ixy>0</ixy>
            <ixz>0</ixz>
            <iyy>0.0001</iyy>
            <iyz>0</iyz>
            <izz>0.0001</izz>
          </inertia>
          <pose frame=''>0 0 0 0 -0 0</pose>
        </inertial>
        <visual name='base_main_viz'>
          <geometry>
            <mesh>
              <scale>0.001 0.001 0.001</scale>
              <uri>model://gimbal_small_2d/meshes/base_main.dae</uri>
            </mesh>
          </geometry>
          <material>
            <script>
              <uri>file://media/materials/scripts/gazebo.material</uri>
              <name>Gazebo/FlatBlack</name>
            </script>
          </material>
        </visual>
        <visual name='base_arm_viz'>
          <geometry>
            <mesh>
              <scale>0.001 0.001 0.001</scale>
              <uri>model://gimbal_small_2d/meshes/base_arm.dae</uri>
            </mesh>
          </geometry>
          <material>
            <script>
              <uri>file://media/materials/scripts/gazebo.material</uri>
              <name>Gazebo/FlatBlack</name>
            </script>
          </material>
        </visual>
        <collision name='base_col'>
          <pose frame=''>0.01 0.075 -0.025 0 -0 0</pose>
          <geometry>
            <box>
              <size>0.1 0.05 0.15</size>
            </box>
          </geometry>
          <surface>
            <friction>
              <ode>
                <mu>1</mu>
                <mu2>1</mu2>
                <fdir1>0 0 0</fdir1>
                <slip1>0</slip1>
                <slip2>0</slip2>
              </ode>
              <torsional>
                <ode/>
              </torsional>
            </friction>
            <contact>
              <ode/>
            </contact>
            <bounce/>
          </surface>
          <max_contacts>10</max_contacts>
        </collision>
        <pose frame=''>0 -0.01 0.07 1.57 0 -1.57</pose>
        <self_collide>0</self_collide>
        <enable_wind>0</enable_wind>
        <kinematic>0</kinematic>
      </link>
      <link name='iris_demo::gimbal_small_2d::tilt_link'>
        <inertial>
          <mass>0.01</mass>
          <inertia>
            <ixx>1e-05</ixx>
            <ixy>0</ixy>
            <ixz>0</ixz>
            <iyy>1e-05</iyy>
            <iyz>0</iyz>
            <izz>1e-05</izz>
          </inertia>
          <pose frame=''>0 0 0 0 -0 0</pose>
        </inertial>
        <visual name='tilt_viz'>
          <pose frame=''>0 0 -0.005 0 -0 0</pose>
          <geometry>
            <mesh>
              <scale>0.001 0.001 0.001</scale>
              <uri>model://gimbal_small_2d/meshes/tilt.dae</uri>
            </mesh>
          </geometry>
          <material>
            <script>
              <uri>file://media/materials/scripts/gazebo.material</uri>
              <name>Gazebo/Grey</name>
            </script>
          </material>
        </visual>
        <collision name='tilt_col'>
          <pose frame=''>0 0 -0.005 0 -0 0</pose>
          <geometry>
            <mesh>
              <scale>0.001 0.001 0.001</scale>
              <uri>model://gimbal_small_2d/meshes/tilt.dae</uri>
            </mesh>
          </geometry>
          <max_contacts>10</max_contacts>
          <surface>
            <contact>
              <ode/>
            </contact>
            <bounce/>
            <friction>
              <torsional>
                <ode/>
              </torsional>
              <ode/>
            </friction>
          </surface>
        </collision>
        <visual name='camera_viz'>
          <pose frame=''>0 0 0.02 0 0 0</pose>
          <geometry>
            <cylinder>
              <radius>0.025</radius>
              <length>0.05</length>
            </cylinder>
          </geometry>
          <material>
            <script>
              <uri>file://media/materials/scripts/gazebo.material</uri>
              <name>Gazebo/Grey</name>
            </script>
          </material>
        </visual>
        <collision name='camera_col'>
          <pose frame=''>0 0 0.02 0 -0 0</pose>
          <geometry>
            <cylinder>
              <radius>0.025</radius>
              <length>0.05</length>
            </cylinder>
          </geometry>
          <max_contacts>10</max_contacts>
          <surface>
            <contact>
              <ode/>
            </contact>
            <bounce/>
            <friction>
              <torsional>
                <ode/>
              </torsional>
              <ode/>
            </friction>
          </surface>
        </collision>
        <sensor name='camera' type='camera'>
          <pose frame=''>0 0 0 -1.57 -1.57 0</pose>
          <camera name='__default__'>
            <horizontal_fov>2</horizontal_fov>
            <image>
              <width>640</width>
              <height>480</height>
            </image>
            <clip>
              <near>0.05</near>
              <far>15000</far>
            </clip>
          </camera>
          <always_on>1</always_on>
          <update_rate>10</update_rate>
          <visualize>1</visualize>
        </sensor>
        <pose frame=''>0 -0.01 0.07 1.57 0 -1.57</pose>
        <self_collide>0</self_collide>
        <enable_wind>0</enable_wind>
        <kinematic>0</kinematic>
      </link>
      <joint name='iris_demo::gimbal_small_2d::tilt_joint' type='revolute'>
        <parent>iris_demo::gimbal_small_2d::base_link</parent>
        <child>iris_demo::gimbal_small_2d::tilt_link</child>
        <physics>
          <ode>
            <implicit_spring_damper>1</implicit_spring_damper>
            <limit>
              <cfm>0</cfm>
              <erp>0.2</erp>
            </limit>
          </ode>
        </physics>
        <axis>
          <xyz>0.000796 -1 0</xyz>
          <dynamics>
            <damping>0.5</damping>
            <spring_reference>0</spring_reference>
            <spring_stiffness>0</spring_stiffness>
          </dynamics>
          <use_parent_model_frame>1</use_parent_model_frame>
          <limit>
            <lower>-0.1</lower>
            <upper>3.14159</upper>
            <effort>10</effort>
            <velocity>-1</velocity>
          </limit>
        </axis>
        <pose frame=''>0 0 0.02 0 -0 0</pose>
      </joint>
      <plugin name='gimbal_small_2d' filename='libGimbalSmall2dPlugin.so'>
        <joint>iris_demo::gimbal_small_2d::tilt_joint</joint>
      </plugin>
      <joint name='iris_demo::iris_gimbal_mount' type='revolute'>
        <parent>iris_demo::iris::base_link</parent>
        <child>iris_demo::gimbal_small_2d::base_link</child>
        <axis>
          <limit>
            <lower>0</lower>
            <upper>0</upper>
          </limit>
          <xyz>0 0 1</xyz>
          <use_parent_model_frame>1</use_parent_model_frame>
          <dynamics>
            <spring_reference>0</spring_reference>
            <spring_stiffness>0</spring_stiffness>
          </dynamics>
        </axis>
      </joint>
      <link name='iris_demo::cam_link'>
        <pose frame=''>0 0 0 0 -0 0</pose>
        <inertial>
          <mass>0.01</mass>
          <inertia>
            <ixx>0.0001</ixx>
            <iyy>0.0001</iyy>
            <izz>0.0001</izz>
            <ixy>0</ixy>
            <ixz>0</ixz>
            <iyz>0</iyz>
          </inertia>
          <pose frame=''>0 0 0 0 -0 0</pose>
        </inertial>
        <sensor name='chase_cam' type='camera'>
          <pose frame=''>-2 0 0.6 0 0.37 0</pose>
          <camera name='__default__'>
            <horizontal_fov>1.2</horizontal_fov>
            <image>
              <width>1920</width>
              <height>1080</height>
            </image>
            <clip>
              <near>0.1</near>
              <far>1000</far>
            </clip>
          </camera>
          <always_on>0</always_on>
          <update_rate>60</update_rate>
          <visualize>1</visualize>
        </sensor>
        <self_collide>0</self_collide>
        <enable_wind>0</enable_wind>
        <kinematic>0</kinematic>
      </link>
      <joint name='iris_demo::camera_mount' type='fixed'>
        <child>iris_demo::cam_link</child>
        <parent>iris_demo::iris::base_link</parent>
        <axis>
          <xyz>0 0 1</xyz>
          <limit>
            <upper>0</upper>
            <lower>0</lower>
          </limit>
          <use_parent_model_frame>0</use_parent_model_frame>
        </axis>
      </joint>
      <plugin name='rotor_0_blade_1' filename='libLiftDragPlugin.so'>
        <a0>0.3</a0>
        <alpha_stall>1.4</alpha_stall>
        <cla>4.2500</cla>
        <cda>0.10</cda>
        <cma>0.00</cma>
        <cla_stall>-0.025</cla_stall>
        <cda_stall>0.0</cda_stall>
        <cma_stall>0.0</cma_stall>
        <area>0.002</area>
        <air_density>1.2041</air_density>
        <cp>0.084 0 0</cp>
        <forward>0 1 0</forward>
        <upward>0 0 1</upward>
        <link_name>iris_demo::iris::rotor_0</link_name>
      </plugin>
      <plugin name='rotor_0_blade_2' filename='libLiftDragPlugin.so'>
        <a0>0.3</a0>
        <alpha_stall>1.4</alpha_stall>
        <cla>4.2500</cla>
        <cda>0.10</cda>
        <cma>0.00</cma>
        <cla_stall>-0.025</cla_stall>
        <cda_stall>0.0</cda_stall>
        <cma_stall>0.0</cma_stall>
        <area>0.002</area>
        <air_density>1.2041</air_density>
        <cp>-0.084 0 0</cp>
        <forward>0 -1 0</forward>
        <upward>0 0 1</upward>
        <link_name>iris_demo::iris::rotor_0</link_name>
      </plugin>
      <plugin name='rotor_1_blade_1' filename='libLiftDragPlugin.so'>
        <a0>0.3</a0>
        <alpha_stall>1.4</alpha_stall>
        <cla>4.2500</cla>
        <cda>0.10</cda>
        <cma>0.00</cma>
        <cla_stall>-0.025</cla_stall>
        <cda_stall>0.0</cda_stall>
        <cma_stall>0.0</cma_stall>
        <area>0.002</area>
        <air_density>1.2041</air_density>
        <cp>0.084 0 0</cp>
        <forward>0 1 0</forward>
        <upward>0 0 1</upward>
        <link_name>iris_demo::iris::rotor_1</link_name>
      </plugin>
      <plugin name='rotor_1_blade_2' filename='libLiftDragPlugin.so'>
        <a0>0.3</a0>
        <alpha_stall>1.4</alpha_stall>
        <cla>4.2500</cla>
        <cda>0.10</cda>
        <cma>0.00</cma>
        <cla_stall>-0.025</cla_stall>
        <cda_stall>0.0</cda_stall>
        <cma_stall>0.0</cma_stall>
        <area>0.002</area>
        <air_density>1.2041</air_density>
        <cp>-0.084 0 0</cp>
        <forward>0 -1 0</forward>
        <upward>0 0 1</upward>
        <link_name>iris_demo::iris::rotor_1</link_name>
      </plugin>
      <plugin name='rotor_2_blade_1' filename='libLiftDragPlugin.so'>
        <a0>0.3</a0>
        <alpha_stall>1.4</alpha_stall>
        <cla>4.2500</cla>
        <cda>0.10</cda>
        <cma>0.00</cma>
        <cla_stall>-0.025</cla_stall>
        <cda_stall>0.0</cda_stall>
        <cma_stall>0.0</cma_stall>
        <area>0.002</area>
        <air_density>1.2041</air_density>
        <cp>0.084 0 0</cp>
        <forward>0 -1 0</forward>
        <upward>0 0 1</upward>
        <link_name>iris_demo::iris::rotor_2</link_name>
      </plugin>
      <plugin name='rotor_2_blade_2' filename='libLiftDragPlugin.so'>
        <a0>0.3</a0>
        <alpha_stall>1.4</alpha_stall>
        <cla>4.2500</cla>
        <cda>0.10</cda>
        <cma>0.00</cma>
        <cla_stall>-0.025</cla_stall>
        <cda_stall>0.0</cda_stall>
        <cma_stall>0.0</cma_stall>
        <area>0.002</area>
        <air_density>1.2041</air_density>
        <cp>-0.084 0 0</cp>
        <forward>0 1 0</forward>
        <upward>0 0 1</upward>
        <link_name>iris_demo::iris::rotor_2</link_name>
      </plugin>
      <plugin name='rotor_3_blade_1' filename='libLiftDragPlugin.so'>
        <a0>0.3</a0>
        <alpha_stall>1.4</alpha_stall>
        <cla>4.2500</cla>
        <cda>0.10</cda>
        <cma>0.00</cma>
        <cla_stall>-0.025</cla_stall>
        <cda_stall>0.0</cda_stall>
        <cma_stall>0.0</cma_stall>
        <area>0.002</area>
        <air_density>1.2041</air_density>
        <cp>0.084 0 0</cp>
        <forward>0 -1 0</forward>
        <upward>0 0 1</upward>
        <link_name>iris_demo::iris::rotor_3</link_name>
      </plugin>
      <plugin name='rotor_3_blade_2' filename='libLiftDragPlugin.so'>
        <a0>0.3</a0>
        <alpha_stall>1.4</alpha_stall>
        <cla>4.2500</cla>
        <cda>0.10</cda>
        <cma>0.00</cma>
        <cla_stall>-0.025</cla_stall>
        <cda_stall>0.0</cda_stall>
        <cma_stall>0.0</cma_stall>
        <area>0.002</area>
        <air_density>1.2041</air_density>
        <cp>-0.084 0 0</cp>
        <forward>0 1 0</forward>
        <upward>0 0 1</upward>
        <link_name>iris_demo::iris::rotor_3</link_name>
      </plugin>
      <plugin name='arducopter_plugin' filename='libArduPilotPlugin.so'>
        <fdm_addr>127.0.0.1</fdm_addr>
        <fdm_port_in>9002</fdm_port_in>
        <fdm_port_out>9003</fdm_port_out>
        <modelXYZToAirplaneXForwardZDown>0 0 0 3.141593 0 0</modelXYZToAirplaneXForwardZDown>
        <gazeboXYZToNED>0 0 0 3.141593 0 0</gazeboXYZToNED>
        <imuName>iris_demo::iris::iris/imu_link::imu_sensor</imuName>
        <connectionTimeoutMaxCount>5</connectionTimeoutMaxCount>
        <control channel='0'>
          <type>VELOCITY</type>
          <offset>0</offset>
          <p_gain>0.20</p_gain>
          <i_gain>0</i_gain>
          <d_gain>0</d_gain>
          <i_max>0</i_max>
          <i_min>0</i_min>
          <cmd_max>2.5</cmd_max>
          <cmd_min>-2.5</cmd_min>
          <jointName>iris_demo::iris::rotor_0_joint</jointName>
          <multiplier>838</multiplier>
          <controlVelocitySlowdownSim>1</controlVelocitySlowdownSim>
        </control>
        <control channel='1'>
          <type>VELOCITY</type>
          <offset>0</offset>
          <p_gain>0.20</p_gain>
          <i_gain>0</i_gain>
          <d_gain>0</d_gain>
          <i_max>0</i_max>
          <i_min>0</i_min>
          <cmd_max>2.5</cmd_max>
          <cmd_min>-2.5</cmd_min>
          <jointName>iris_demo::iris::rotor_1_joint</jointName>
          <multiplier>838</multiplier>
          <controlVelocitySlowdownSim>1</controlVelocitySlowdownSim>
        </control>
        <control channel='2'>
          <type>VELOCITY</type>
          <offset>0</offset>
          <p_gain>0.20</p_gain>
          <i_gain>0</i_gain>
          <d_gain>0</d_gain>
          <i_max>0</i_max>
          <i_min>0</i_min>
          <cmd_max>2.5</cmd_max>
          <cmd_min>-2.5</cmd_min>
          <jointName>iris_demo::iris::rotor_2_joint</jointName>
          <multiplier>-838</multiplier>
          <controlVelocitySlowdownSim>1</controlVelocitySlowdownSim>
        </control>
        <control channel='3'>
          <type>VELOCITY</type>
          <offset>0</offset>
          <p_gain>0.20</p_gain>
          <i_gain>0</i_gain>
          <d_gain>0</d_gain>
          <i_max>0</i_max>
          <i_min>0</i_min>
          <cmd_max>2.5</cmd_max>
          <cmd_min>-2.5</cmd_min>
          <jointName>iris_demo::iris::rotor_3_joint</jointName>
          <multiplier>-838</multiplier>
          <controlVelocitySlowdownSim>1</controlVelocitySlowdownSim>
        </control>
      </plugin>
      <pose frame=''>0 0 0 0 -0 0</pose>
      <link name='camera'>
        <pose frame=''>0 -0.01 0.07 -1.57 -0 1.57</pose>
        <inertial>
          <pose frame=''>0 0 0 0 -0 0</pose>
          <mass>0.1</mass>
          <inertia>
            <ixx>0.001</ixx>
            <ixy>0</ixy>
            <ixz>0</ixz>
            <iyy>0.001</iyy>
            <iyz>0</iyz>
            <izz>0.001</izz>
          </inertia>
        </inertial>
        <visual name='visual'>
          <pose frame=''>0 0 0 0 -0 0</pose>
          <geometry>
            <cylinder>
              <radius>0.025</radius>
              <length>0.025</length>
            </cylinder>
          </geometry>
          <material>
            <script>
              <uri>file://media/materials/scripts/gazebo.material</uri>
              <name>Gazebo/Grey</name>
            </script>
          </material>
        </visual>
        <sensor name='camera' type='camera'>
          <pose frame=''>0 0 0 1.57 -1.57 0</pose>
          <camera name='__default__'>
            <horizontal_fov>1.0472</horizontal_fov>
            <image>
              <width>640</width>
              <height>480</height>
            </image>
            <clip>
              <near>0.05</near>
              <far>1000</far>
            </clip>
          </camera>
          <always_on>1</always_on>
          <update_rate>10</update_rate>
          <visualize>1</visualize>
          <plugin name='camera_controller' filename='libgazebo_ros_camera.so'>
            <alwaysOn>1</alwaysOn>
            <updateRate>0.0</updateRate>
            <cameraName>webcam</cameraName>
            <imageTopicName>image_raw</imageTopicName>
            <cameraInfoTopicName>camera_info</cameraInfoTopicName>
            <frameName>camera_link</frameName>
            <hackBaseline>0.07</hackBaseline>
            <distortionK1>0.0</distortionK1>
            <distortionK2>0.0</distortionK2>
            <distortionK3>0.0</distortionK3>
            <distortionT1>0.0</distortionT1>
            <distortionT2>0.0</distortionT2>
          </plugin>
        </sensor>
        <self_collide>0</self_collide>
        <enable_wind>0</enable_wind>
        <kinematic>0</kinematic>
      </link>
      <joint name='base_camera_joint' type='revolute'>
        <pose frame=''>0 0 0 0 -0 0</pose>
        <parent>iris::iris_demo::gimbal_small_2d::tilt_link</parent>
        <child>camera</child>
        <axis>
          <limit>
            <lower>0</lower>
            <upper>0</upper>
          </limit>
          <xyz>0 0 1</xyz>
          <use_parent_model_frame>1</use_parent_model_frame>
          <dynamics>
            <spring_reference>0</spring_reference>
            <spring_stiffness>0</spring_stiffness>
          </dynamics>
        </axis>
      </joint>
    </model>
    <gravity>0 0 -9.8</gravity>
    <magnetic_field>6e-06 2.3e-05 -4.2e-05</magnetic_field>
    <atmosphere type='adiabatic'/>
    <scene>
      <ambient>0.4 0.4 0.4 1</ambient>
      <background>0.7 0.7 0.7 1</background>
      <shadows>1</shadows>
    </scene>
    <wind/>
    <spherical_coordinates>
      <surface_model>EARTH_WGS84</surface_model>
      <latitude_deg>0</latitude_deg>
      <longitude_deg>0</longitude_deg>
      <elevation>0</elevation>
      <heading_deg>0</heading_deg>
    </spherical_coordinates>
    <model name='robocup_3d_field'>
      <static>1</static>
      <link name='field'>
        <pose frame=''>0 0 0.01 0 -0 0</pose>
        <collision name='collision'>
          <geometry>
            <plane>
              <normal>0 0 1</normal>
              <size>30 20</size>
            </plane>
          </geometry>
          <surface>
            <friction>
              <ode>
                <mu>100</mu>
                <mu2>50</mu2>
              </ode>
              <torsional>
                <ode/>
              </torsional>
            </friction>
            <contact>
              <ode/>
            </contact>
            <bounce/>
          </surface>
          <max_contacts>10</max_contacts>
        </collision>
        <visual name='base1'>
          <pose frame=''>0 11 0.001 0 -0 0</pose>
          <cast_shadows>0</cast_shadows>
          <geometry>
            <plane>
              <normal>0 0 1</normal>
              <size>34 2</size>
            </plane>
          </geometry>
          <material>
            <script>
              <uri>model://robocup_3Dsim_field/materials/scripts/</uri>
              <uri>model://robocup_3Dsim_field/materials/textures/</uri>
              <name>RoboCup/FieldBorder</name>
            </script>
          </material>
        </visual>
        <visual name='base2'>
          <pose frame=''>0 -11 0.001 0 -0 0</pose>
          <cast_shadows>0</cast_shadows>
          <geometry>
            <plane>
              <normal>0 0 1</normal>
              <size>34 2</size>
            </plane>
          </geometry>
          <material>
            <script>
              <uri>model://robocup_3Dsim_field/materials/scripts/</uri>
              <uri>model://robocup_3Dsim_field/materials/textures/</uri>
              <name>RoboCup/FieldBorder</name>
            </script>
          </material>
        </visual>
        <visual name='base3'>
          <pose frame=''>16 0 0.001 0 -0 0</pose>
          <cast_shadows>0</cast_shadows>
          <geometry>
            <plane>
              <normal>0 0 1</normal>
              <size>2 20</size>
            </plane>
          </geometry>
          <material>
            <script>
              <uri>model://robocup_3Dsim_field/materials/scripts/</uri>
              <uri>model://robocup_3Dsim_field/materials/textures/</uri>
              <name>RoboCup/FieldBorder</name>
            </script>
          </material>
        </visual>
        <visual name='base4'>
          <pose frame=''>-16 0 0.001 0 -0 0</pose>
          <cast_shadows>0</cast_shadows>
          <geometry>
            <plane>
              <normal>0 0 1</normal>
              <size>2 20</size>
            </plane>
          </geometry>
          <material>
            <script>
              <uri>model://robocup_3Dsim_field/materials/scripts/</uri>
              <uri>model://robocup_3Dsim_field/materials/textures/</uri>
              <name>RoboCup/FieldBorder</name>
            </script>
          </material>
        </visual>
        <visual name='carpet'>
          <cast_shadows>0</cast_shadows>
          <geometry>
            <plane>
              <normal>0 0 1</normal>
              <size>30 20</size>
            </plane>
          </geometry>
          <material>
            <script>
              <uri>model://robocup_3Dsim_field/materials/scripts/</uri>
              <uri>model://robocup_3Dsim_field/materials/textures/</uri>
              <name>RoboCup/Grass</name>
            </script>
          </material>
        </visual>
        <self_collide>0</self_collide>
        <enable_wind>0</enable_wind>
        <kinematic>0</kinematic>
      </link>
      <pose frame=''>-0.280458 0.370204 0 0 -0 0</pose>
    </model>
    <model name='RoboCup 2014 SPL Goal'>
      <static>1</static>
      <link name='left_post'>
        <pose frame=''>0 0.8 0.45 0 -0 0</pose>
        <collision name='collision'>
          <geometry>
            <cylinder>
              <radius>0.05</radius>
              <length>0.9</length>
            </cylinder>
          </geometry>
          <max_contacts>10</max_contacts>
          <surface>
            <contact>
              <ode/>
            </contact>
            <bounce/>
            <friction>
              <torsional>
                <ode/>
              </torsional>
              <ode/>
            </friction>
          </surface>
        </collision>
        <visual name='visual'>
          <geometry>
            <cylinder>
              <radius>0.05</radius>
              <length>0.9</length>
            </cylinder>
          </geometry>
          <material>
            <script>
              <uri>file://media/materials/scripts/gazebo.material</uri>
              <name>Gazebo/ZincYellow</name>
            </script>
          </material>
        </visual>
        <self_collide>0</self_collide>
        <enable_wind>0</enable_wind>
        <kinematic>0</kinematic>
      </link>
      <link name='left_support_horiz_lower'>
        <pose frame=''>0.24 0.8 0.01 0 -0 0</pose>
        <collision name='collision'>
          <geometry>
            <box>
              <size>0.38 0.02 0.02</size>
            </box>
          </geometry>
          <max_contacts>10</max_contacts>
          <surface>
            <contact>
              <ode/>
            </contact>
            <bounce/>
            <friction>
              <torsional>
                <ode/>
              </torsional>
              <ode/>
            </friction>
          </surface>
        </collision>
        <visual name='visual'>
          <geometry>
            <box>
              <size>0.38 0.02 0.02</size>
            </box>
          </geometry>
          <material>
            <script>
              <uri>file://media/materials/scripts/gazebo.material</uri>
              <name>Gazebo/White</name>
            </script>
          </material>
        </visual>
        <self_collide>0</self_collide>
        <enable_wind>0</enable_wind>
        <kinematic>0</kinematic>
      </link>
      <link name='left_support_horiz_upper'>
        <pose frame=''>0.24 0.8 0.79 0 -0 0</pose>
        <collision name='collision'>
          <geometry>
            <box>
              <size>0.38 0.02 0.02</size>
            </box>
          </geometry>
          <max_contacts>10</max_contacts>
          <surface>
            <contact>
              <ode/>
            </contact>
            <bounce/>
            <friction>
              <torsional>
                <ode/>
              </torsional>
              <ode/>
            </friction>
          </surface>
        </collision>
        <visual name='visual'>
          <geometry>
            <box>
              <size>0.38 0.02 0.02</size>
            </box>
          </geometry>
          <material>
            <script>
              <uri>file://media/materials/scripts/gazebo.material</uri>
              <name>Gazebo/White</name>
            </script>
          </material>
        </visual>
        <self_collide>0</self_collide>
        <enable_wind>0</enable_wind>
        <kinematic>0</kinematic>
      </link>
      <link name='left_support_vertical'>
        <pose frame=''>0.44 0.8 0.4 3.14159 1.57079 3.14159</pose>
        <collision name='collision'>
          <geometry>
            <box>
              <size>0.8 0.02 0.02</size>
            </box>
          </geometry>
          <max_contacts>10</max_contacts>
          <surface>
            <contact>
              <ode/>
            </contact>
            <bounce/>
            <friction>
              <torsional>
                <ode/>
              </torsional>
              <ode/>
            </friction>
          </surface>
        </collision>
        <visual name='visual'>
          <geometry>
            <box>
              <size>0.8 0.02 0.02</size>
            </box>
          </geometry>
          <material>
            <script>
              <uri>file://media/materials/scripts/gazebo.material</uri>
              <name>Gazebo/White</name>
            </script>
          </material>
        </visual>
        <self_collide>0</self_collide>
        <enable_wind>0</enable_wind>
        <kinematic>0</kinematic>
      </link>
      <link name='right_support_horiz_lower'>
        <pose frame=''>0.24 -0.8 0.01 0 -0 0</pose>
        <collision name='collision'>
          <geometry>
            <box>
              <size>0.38 0.02 0.02</size>
            </box>
          </geometry>
          <max_contacts>10</max_contacts>
          <surface>
            <contact>
              <ode/>
            </contact>
            <bounce/>
            <friction>
              <torsional>
                <ode/>
              </torsional>
              <ode/>
            </friction>
          </surface>
        </collision>
        <visual name='visual'>
          <geometry>
            <box>
              <size>0.38 0.02 0.02</size>
            </box>
          </geometry>
          <material>
            <script>
              <uri>file://media/materials/scripts/gazebo.material</uri>
              <name>Gazebo/White</name>
            </script>
          </material>
        </visual>
        <self_collide>0</self_collide>
        <enable_wind>0</enable_wind>
        <kinematic>0</kinematic>
      </link>
      <link name='right_support_horiz_upper'>
        <pose frame=''>0.24 -0.8 0.79 0 -0 0</pose>
        <collision name='collision'>
          <geometry>
            <box>
              <size>0.38 0.02 0.02</size>
            </box>
          </geometry>
          <max_contacts>10</max_contacts>
          <surface>
            <contact>
              <ode/>
            </contact>
            <bounce/>
            <friction>
              <torsional>
                <ode/>
              </torsional>
              <ode/>
            </friction>
          </surface>
        </collision>
        <visual name='visual'>
          <geometry>
            <box>
              <size>0.38 0.02 0.02</size>
            </box>
          </geometry>
          <material>
            <script>
              <uri>file://media/materials/scripts/gazebo.material</uri>
              <name>Gazebo/White</name>
            </script>
          </material>
        </visual>
        <self_collide>0</self_collide>
        <enable_wind>0</enable_wind>
        <kinematic>0</kinematic>
      </link>
      <link name='right_support_vertical'>
        <pose frame=''>0.44 -0.8 0.4 3.14159 1.57079 3.14159</pose>
        <collision name='collision'>
          <geometry>
            <box>
              <size>0.8 0.02 0.02</size>
            </box>
          </geometry>
          <max_contacts>10</max_contacts>
          <surface>
            <contact>
              <ode/>
            </contact>
            <bounce/>
            <friction>
              <torsional>
                <ode/>
              </torsional>
              <ode/>
            </friction>
          </surface>
        </collision>
        <visual name='visual'>
          <geometry>
            <box>
              <size>0.8 0.02 0.02</size>
            </box>
          </geometry>
          <material>
            <script>
              <uri>file://media/materials/scripts/gazebo.material</uri>
              <name>Gazebo/White</name>
            </script>
          </material>
        </visual>
        <self_collide>0</self_collide>
        <enable_wind>0</enable_wind>
        <kinematic>0</kinematic>
      </link>
      <link name='center_support_horiz_lower'>
        <pose frame=''>0.44 0 0.01 3.14159 1.57079 3.14159</pose>
        <collision name='collision'>
          <geometry>
            <box>
              <size>0.02 1.58 0.02</size>
            </box>
          </geometry>
          <max_contacts>10</max_contacts>
          <surface>
            <contact>
              <ode/>
            </contact>
            <bounce/>
            <friction>
              <torsional>
                <ode/>
              </torsional>
              <ode/>
            </friction>
          </surface>
        </collision>
        <visual name='visual'>
          <geometry>
            <box>
              <size>0.02 1.58 0.02</size>
            </box>
          </geometry>
          <material>
            <script>
              <uri>file://media/materials/scripts/gazebo.material</uri>
              <name>Gazebo/White</name>
            </script>
          </material>
        </visual>
        <self_collide>0</self_collide>
        <enable_wind>0</enable_wind>
        <kinematic>0</kinematic>
      </link>
      <link name='center_support_horiz_upper'>
        <pose frame=''>0.44 0 0.79 3.14159 1.57079 3.14159</pose>
        <collision name='collision'>
          <geometry>
            <box>
              <size>0.02 1.58 0.02</size>
            </box>
          </geometry>
          <max_contacts>10</max_contacts>
          <surface>
            <contact>
              <ode/>
            </contact>
            <bounce/>
            <friction>
              <torsional>
                <ode/>
              </torsional>
              <ode/>
            </friction>
          </surface>
        </collision>
        <visual name='visual'>
          <geometry>
            <box>
              <size>0.02 1.58 0.02</size>
            </box>
          </geometry>
          <material>
            <script>
              <uri>file://media/materials/scripts/gazebo.material</uri>
              <name>Gazebo/White</name>
            </script>
          </material>
        </visual>
        <self_collide>0</self_collide>
        <enable_wind>0</enable_wind>
        <kinematic>0</kinematic>
      </link>
      <link name='right_post'>
        <pose frame=''>0 -0.8 0.45 0 -0 0</pose>
        <collision name='collision'>
          <geometry>
            <cylinder>
              <radius>0.05</radius>
              <length>0.9</length>
            </cylinder>
          </geometry>
          <max_contacts>10</max_contacts>
          <surface>
            <contact>
              <ode/>
            </contact>
            <bounce/>
            <friction>
              <torsional>
                <ode/>
              </torsional>
              <ode/>
            </friction>
          </surface>
        </collision>
        <visual name='visual'>
          <geometry>
            <cylinder>
              <radius>0.05</radius>
              <length>0.9</length>
            </cylinder>
          </geometry>
          <material>
            <script>
              <uri>file://media/materials/scripts/gazebo.material</uri>
              <name>Gazebo/ZincYellow</name>
            </script>
          </material>
        </visual>
        <self_collide>0</self_collide>
        <enable_wind>0</enable_wind>
        <kinematic>0</kinematic>
      </link>
      <link name='crossbar'>
        <pose frame=''>0 0 0.85 1.57 1.57 0</pose>
        <collision name='collision'>
          <geometry>
            <cylinder>
              <radius>0.05</radius>
              <length>1.5</length>
            </cylinder>
          </geometry>
          <max_contacts>10</max_contacts>
          <surface>
            <contact>
              <ode/>
            </contact>
            <bounce/>
            <friction>
              <torsional>
                <ode/>
              </torsional>
              <ode/>
            </friction>
          </surface>
        </collision>
        <visual name='visual'>
          <geometry>
            <cylinder>
              <radius>0.05</radius>
              <length>1.5</length>
            </cylinder>
          </geometry>
          <material>
            <script>
              <uri>file://media/materials/scripts/gazebo.material</uri>
              <name>Gazebo/ZincYellow</name>
            </script>
          </material>
        </visual>
        <self_collide>0</self_collide>
        <enable_wind>0</enable_wind>
        <kinematic>0</kinematic>
      </link>
      <link name='center_net'>
        <pose frame=''>0.44 0 0.4 0 -0 0</pose>
        <collision name='collision'>
          <geometry>
            <box>
              <size>0.01 1.6 0.8</size>
            </box>
          </geometry>
          <max_contacts>10</max_contacts>
          <surface>
            <contact>
              <ode/>
            </contact>
            <bounce/>
            <friction>
              <torsional>
                <ode/>
              </torsional>
              <ode/>
            </friction>
          </surface>
        </collision>
        <visual name='visual'>
          <geometry>
            <box>
              <size>0.01 1.6 0.8</size>
            </box>
          </geometry>
          <material>
            <script>
              <uri>model://robocup09_spl_field/materials/scripts/</uri>
              <uri>model://robocup09_spl_field/materials/textures/</uri>
              <name>RoboCup/Net</name>
            </script>
          </material>
        </visual>
        <self_collide>0</self_collide>
        <enable_wind>0</enable_wind>
        <kinematic>0</kinematic>
      </link>
      <link name='left_net'>
        <pose frame=''>0.24 0.8 0.4 0 -0 0</pose>
        <collision name='collision'>
          <geometry>
            <box>
              <size>0.38 0.01 0.76</size>
            </box>
          </geometry>
          <max_contacts>10</max_contacts>
          <surface>
            <contact>
              <ode/>
            </contact>
            <bounce/>
            <friction>
              <torsional>
                <ode/>
              </torsional>
              <ode/>
            </friction>
          </surface>
        </collision>
        <visual name='visual'>
          <geometry>
            <box>
              <size>0.38 0.01 0.76</size>
            </box>
          </geometry>
          <material>
            <script>
              <uri>model://robocup09_spl_field/materials/scripts/</uri>
              <uri>model://robocup09_spl_field/materials/textures/</uri>
              <name>RoboCup/Net</name>
            </script>
          </material>
        </visual>
        <self_collide>0</self_collide>
        <enable_wind>0</enable_wind>
        <kinematic>0</kinematic>
      </link>
      <link name='right_net'>
        <pose frame=''>0.24 -0.8 0.4 0 -0 0</pose>
        <collision name='collision'>
          <geometry>
            <box>
              <size>0.38 0.01 0.76</size>
            </box>
          </geometry>
          <max_contacts>10</max_contacts>
          <surface>
            <contact>
              <ode/>
            </contact>
            <bounce/>
            <friction>
              <torsional>
                <ode/>
              </torsional>
              <ode/>
            </friction>
          </surface>
        </collision>
        <visual name='visual'>
          <geometry>
            <box>
              <size>0.38 0.01 0.76</size>
            </box>
          </geometry>
          <material>
            <script>
              <uri>model://robocup09_spl_field/materials/scripts/</uri>
              <uri>model://robocup09_spl_field/materials/textures/</uri>
              <name>RoboCup/Net</name>
            </script>
          </material>
        </visual>
        <self_collide>0</self_collide>
        <enable_wind>0</enable_wind>
        <kinematic>0</kinematic>
      </link>
      <pose frame=''>14.2398 -0.350873 0 0 -0 0</pose>
    </model>
    <model name='robocup_3d_goal'>
      <static>1</static>
      <link name='left_post'>
        <pose frame=''>0 1.05 0.45 0 -0 0</pose>
        <collision name='collision'>
          <geometry>
            <cylinder>
              <radius>0.05</radius>
              <length>0.9</length>
            </cylinder>
          </geometry>
          <max_contacts>10</max_contacts>
          <surface>
            <contact>
              <ode/>
            </contact>
            <bounce/>
            <friction>
              <torsional>
                <ode/>
              </torsional>
              <ode/>
            </friction>
          </surface>
        </collision>
        <visual name='visual'>
          <geometry>
            <cylinder>
              <radius>0.05</radius>
              <length>0.9</length>
            </cylinder>
          </geometry>
          <material>
            <script>
              <uri>file://media/materials/scripts/gazebo.material</uri>
              <name>Gazebo/ZincYellow</name>
            </script>
          </material>
        </visual>
        <self_collide>0</self_collide>
        <enable_wind>0</enable_wind>
        <kinematic>0</kinematic>
      </link>
      <link name='left_support_horiz_lower'>
        <pose frame=''>0.3 1.05 0.01 0 -0 0</pose>
        <collision name='collision'>
          <geometry>
            <box>
              <size>0.5 0.02 0.02</size>
            </box>
          </geometry>
          <max_contacts>10</max_contacts>
          <surface>
            <contact>
              <ode/>
            </contact>
            <bounce/>
            <friction>
              <torsional>
                <ode/>
              </torsional>
              <ode/>
            </friction>
          </surface>
        </collision>
        <visual name='visual'>
          <geometry>
            <box>
              <size>0.5 0.02 0.02</size>
            </box>
          </geometry>
          <material>
            <script>
              <uri>file://media/materials/scripts/gazebo.material</uri>
              <name>Gazebo/White</name>
            </script>
          </material>
        </visual>
        <self_collide>0</self_collide>
        <enable_wind>0</enable_wind>
        <kinematic>0</kinematic>
      </link>
      <link name='left_support_horiz_upper'>
        <pose frame=''>0.3 1.05 0.79 0 -0 0</pose>
        <collision name='collision'>
          <geometry>
            <box>
              <size>0.5 0.02 0.02</size>
            </box>
          </geometry>
          <max_contacts>10</max_contacts>
          <surface>
            <contact>
              <ode/>
            </contact>
            <bounce/>
            <friction>
              <torsional>
                <ode/>
              </torsional>
              <ode/>
            </friction>
          </surface>
        </collision>
        <visual name='visual'>
          <geometry>
            <box>
              <size>0.5 0.02 0.02</size>
            </box>
          </geometry>
          <material>
            <script>
              <uri>file://media/materials/scripts/gazebo.material</uri>
              <name>Gazebo/White</name>
            </script>
          </material>
        </visual>
        <self_collide>0</self_collide>
        <enable_wind>0</enable_wind>
        <kinematic>0</kinematic>
      </link>
      <link name='left_support_vertical'>
        <pose frame=''>0.56 1.05 0.4 3.14159 1.57079 3.14159</pose>
        <collision name='collision'>
          <geometry>
            <box>
              <size>0.8 0.02 0.02</size>
            </box>
          </geometry>
          <max_contacts>10</max_contacts>
          <surface>
            <contact>
              <ode/>
            </contact>
            <bounce/>
            <friction>
              <torsional>
                <ode/>
              </torsional>
              <ode/>
            </friction>
          </surface>
        </collision>
        <visual name='visual'>
          <geometry>
            <box>
              <size>0.8 0.02 0.02</size>
            </box>
          </geometry>
          <material>
            <script>
              <uri>file://media/materials/scripts/gazebo.material</uri>
              <name>Gazebo/White</name>
            </script>
          </material>
        </visual>
        <self_collide>0</self_collide>
        <enable_wind>0</enable_wind>
        <kinematic>0</kinematic>
      </link>
      <link name='right_support_horiz_lower'>
        <pose frame=''>0.3 -1.05 0.01 0 -0 0</pose>
        <collision name='collision'>
          <geometry>
            <box>
              <size>0.5 0.02 0.02</size>
            </box>
          </geometry>
          <max_contacts>10</max_contacts>
          <surface>
            <contact>
              <ode/>
            </contact>
            <bounce/>
            <friction>
              <torsional>
                <ode/>
              </torsional>
              <ode/>
            </friction>
          </surface>
        </collision>
        <visual name='visual'>
          <geometry>
            <box>
              <size>0.5 0.02 0.02</size>
            </box>
          </geometry>
          <material>
            <script>
              <uri>file://media/materials/scripts/gazebo.material</uri>
              <name>Gazebo/White</name>
            </script>
          </material>
        </visual>
        <self_collide>0</self_collide>
        <enable_wind>0</enable_wind>
        <kinematic>0</kinematic>
      </link>
      <link name='right_support_horiz_upper'>
        <pose frame=''>0.3 -1.05 0.79 0 -0 0</pose>
        <collision name='collision'>
          <geometry>
            <box>
              <size>0.5 0.02 0.02</size>
            </box>
          </geometry>
          <max_contacts>10</max_contacts>
          <surface>
            <contact>
              <ode/>
            </contact>
            <bounce/>
            <friction>
              <torsional>
                <ode/>
              </torsional>
              <ode/>
            </friction>
          </surface>
        </collision>
        <visual name='visual'>
          <geometry>
            <box>
              <size>0.5 0.02 0.02</size>
            </box>
          </geometry>
          <material>
            <script>
              <uri>file://media/materials/scripts/gazebo.material</uri>
              <name>Gazebo/White</name>
            </script>
          </material>
        </visual>
        <self_collide>0</self_collide>
        <enable_wind>0</enable_wind>
        <kinematic>0</kinematic>
      </link>
      <link name='right_support_vertical'>
        <pose frame=''>0.56 -1.05 0.4 3.14159 1.57079 3.14159</pose>
        <collision name='collision'>
          <geometry>
            <box>
              <size>0.8 0.02 0.02</size>
            </box>
          </geometry>
          <max_contacts>10</max_contacts>
          <surface>
            <contact>
              <ode/>
            </contact>
            <bounce/>
            <friction>
              <torsional>
                <ode/>
              </torsional>
              <ode/>
            </friction>
          </surface>
        </collision>
        <visual name='visual'>
          <geometry>
            <box>
              <size>0.8 0.02 0.02</size>
            </box>
          </geometry>
          <material>
            <script>
              <uri>file://media/materials/scripts/gazebo.material</uri>
              <name>Gazebo/White</name>
            </script>
          </material>
        </visual>
        <self_collide>0</self_collide>
        <enable_wind>0</enable_wind>
        <kinematic>0</kinematic>
      </link>
      <link name='center_support_horiz_lower'>
        <pose frame=''>0.56 0 0.01 3.14159 1.57079 3.14159</pose>
        <collision name='collision'>
          <geometry>
            <box>
              <size>0.02 2.08 0.02</size>
            </box>
          </geometry>
          <max_contacts>10</max_contacts>
          <surface>
            <contact>
              <ode/>
            </contact>
            <bounce/>
            <friction>
              <torsional>
                <ode/>
              </torsional>
              <ode/>
            </friction>
          </surface>
        </collision>
        <visual name='visual'>
          <geometry>
            <box>
              <size>0.02 2.08 0.02</size>
            </box>
          </geometry>
          <material>
            <script>
              <uri>file://media/materials/scripts/gazebo.material</uri>
              <name>Gazebo/White</name>
            </script>
          </material>
        </visual>
        <self_collide>0</self_collide>
        <enable_wind>0</enable_wind>
        <kinematic>0</kinematic>
      </link>
      <link name='center_support_horiz_upper'>
        <pose frame=''>0.56 0 0.79 3.14159 1.57079 3.14159</pose>
        <collision name='collision'>
          <geometry>
            <box>
              <size>0.02 2.08 0.02</size>
            </box>
          </geometry>
          <max_contacts>10</max_contacts>
          <surface>
            <contact>
              <ode/>
            </contact>
            <bounce/>
            <friction>
              <torsional>
                <ode/>
              </torsional>
              <ode/>
            </friction>
          </surface>
        </collision>
        <visual name='visual'>
          <geometry>
            <box>
              <size>0.02 2.08 0.02</size>
            </box>
          </geometry>
          <material>
            <script>
              <uri>file://media/materials/scripts/gazebo.material</uri>
              <name>Gazebo/White</name>
            </script>
          </material>
        </visual>
        <self_collide>0</self_collide>
        <enable_wind>0</enable_wind>
        <kinematic>0</kinematic>
      </link>
      <link name='right_post'>
        <pose frame=''>0 -1.05 0.45 0 -0 0</pose>
        <collision name='collision'>
          <geometry>
            <cylinder>
              <radius>0.05</radius>
              <length>0.9</length>
            </cylinder>
          </geometry>
          <max_contacts>10</max_contacts>
          <surface>
            <contact>
              <ode/>
            </contact>
            <bounce/>
            <friction>
              <torsional>
                <ode/>
              </torsional>
              <ode/>
            </friction>
          </surface>
        </collision>
        <visual name='visual'>
          <geometry>
            <cylinder>
              <radius>0.05</radius>
              <length>0.9</length>
            </cylinder>
          </geometry>
          <material>
            <script>
              <uri>file://media/materials/scripts/gazebo.material</uri>
              <name>Gazebo/ZincYellow</name>
            </script>
          </material>
        </visual>
        <self_collide>0</self_collide>
        <enable_wind>0</enable_wind>
        <kinematic>0</kinematic>
      </link>
      <link name='crossbar'>
        <pose frame=''>0 0 0.85 1.57 1.57 0</pose>
        <collision name='collision'>
          <geometry>
            <cylinder>
              <radius>0.05</radius>
              <length>2</length>
            </cylinder>
          </geometry>
          <max_contacts>10</max_contacts>
          <surface>
            <contact>
              <ode/>
            </contact>
            <bounce/>
            <friction>
              <torsional>
                <ode/>
              </torsional>
              <ode/>
            </friction>
          </surface>
        </collision>
        <visual name='visual'>
          <geometry>
            <cylinder>
              <radius>0.05</radius>
              <length>2</length>
            </cylinder>
          </geometry>
          <material>
            <script>
              <uri>file://media/materials/scripts/gazebo.material</uri>
              <name>Gazebo/ZincYellow</name>
            </script>
          </material>
        </visual>
        <self_collide>0</self_collide>
        <enable_wind>0</enable_wind>
        <kinematic>0</kinematic>
      </link>
      <link name='center_net'>
        <pose frame=''>0.56 0 0.4 0 -0 0</pose>
        <collision name='collision'>
          <geometry>
            <box>
              <size>0.01 2.1 0.8</size>
            </box>
          </geometry>
          <max_contacts>10</max_contacts>
          <surface>
            <contact>
              <ode/>
            </contact>
            <bounce/>
            <friction>
              <torsional>
                <ode/>
              </torsional>
              <ode/>
            </friction>
          </surface>
        </collision>
        <visual name='visual'>
          <geometry>
            <box>
              <size>0.01 2.1 0.8</size>
            </box>
          </geometry>
          <material>
            <script>
              <uri>model://robocup09_spl_field/materials/scripts/</uri>
              <uri>model://robocup09_spl_field/materials/textures/</uri>
              <name>RoboCup/Net</name>
            </script>
          </material>
        </visual>
        <self_collide>0</self_collide>
        <enable_wind>0</enable_wind>
        <kinematic>0</kinematic>
      </link>
      <link name='left_net'>
        <pose frame=''>0.3 1.05 0.4 0 -0 0</pose>
        <collision name='collision'>
          <geometry>
            <box>
              <size>0.5 0.01 0.76</size>
            </box>
          </geometry>
          <max_contacts>10</max_contacts>
          <surface>
            <contact>
              <ode/>
            </contact>
            <bounce/>
            <friction>
              <torsional>
                <ode/>
              </torsional>
              <ode/>
            </friction>
          </surface>
        </collision>
        <visual name='visual'>
          <geometry>
            <box>
              <size>0.5 0.01 0.76</size>
            </box>
          </geometry>
          <material>
            <script>
              <uri>model://robocup09_spl_field/materials/scripts/</uri>
              <uri>model://robocup09_spl_field/materials/textures/</uri>
              <name>RoboCup/Net</name>
            </script>
          </material>
        </visual>
        <self_collide>0</self_collide>
        <enable_wind>0</enable_wind>
        <kinematic>0</kinematic>
      </link>
      <link name='right_net'>
        <pose frame=''>0.3 -1.05 0.4 0 -0 0</pose>
        <collision name='collision'>
          <geometry>
            <box>
              <size>0.5 0.01 0.76</size>
            </box>
          </geometry>
          <max_contacts>10</max_contacts>
          <surface>
            <contact>
              <ode/>
            </contact>
            <bounce/>
            <friction>
              <torsional>
                <ode/>
              </torsional>
              <ode/>
            </friction>
          </surface>
        </collision>
        <visual name='visual'>
          <geometry>
            <box>
              <size>0.5 0.01 0.76</size>
            </box>
          </geometry>
          <material>
            <script>
              <uri>model://robocup09_spl_field/materials/scripts/</uri>
              <uri>model://robocup09_spl_field/materials/textures/</uri>
              <name>RoboCup/Net</name>
            </script>
          </material>
        </visual>
        <self_collide>0</self_collide>
        <enable_wind>0</enable_wind>
        <kinematic>0</kinematic>
      </link>
      <pose frame=''>-14.7608 -0.044315 0 0 -0 0</pose>
    </model>
    <model name='person_standing'>
      <link name='link'>
        <inertial>
          <pose frame=''>0 -0.1 0.95 0 -0 0</pose>
          <mass>80</mass>
          <inertia>
            <ixx>24.88</ixx>
            <ixy>0</ixy>
            <ixz>0</ixz>
            <iyy>25.73</iyy>
            <iyz>0</iyz>
            <izz>2.48</izz>
          </inertia>
        </inertial>
        <collision name='bottom'>
          <pose frame=''>0 -0.1 0.01 0 -0 0</pose>
          <geometry>
            <box>
              <size>0.5 0.35 0.02</size>
            </box>
          </geometry>
          <max_contacts>10</max_contacts>
          <surface>
            <contact>
              <ode/>
            </contact>
            <bounce/>
            <friction>
              <torsional>
                <ode/>
              </torsional>
              <ode/>
            </friction>
          </surface>
        </collision>
        <collision name='person'>
          <pose frame=''>0 0 0.02 0.04 -0 0</pose>
          <geometry>
            <mesh>
              <uri>model://person_standing/meshes/standing.dae</uri>
            </mesh>
          </geometry>
          <max_contacts>10</max_contacts>
          <surface>
            <contact>
              <ode/>
            </contact>
            <bounce/>
            <friction>
              <torsional>
                <ode/>
              </torsional>
              <ode/>
            </friction>
          </surface>
        </collision>
        <visual name='visual'>
          <pose frame=''>0 0 0.02 0.04 -0 0</pose>
          <geometry>
            <mesh>
              <uri>model://person_standing/meshes/standing.dae</uri>
            </mesh>
          </geometry>
        </visual>
        <self_collide>0</self_collide>
        <enable_wind>0</enable_wind>
        <kinematic>0</kinematic>
      </link>
      <pose frame=''>-4.22802 -6.53935 0 0 -0 0</pose>
    </model>
    <model name='person_standing_0'>
      <link name='link'>
        <inertial>
          <pose frame=''>0 -0.1 0.95 0 -0 0</pose>
          <mass>80</mass>
          <inertia>
            <ixx>24.88</ixx>
            <ixy>0</ixy>
            <ixz>0</ixz>
            <iyy>25.73</iyy>
            <iyz>0</iyz>
            <izz>2.48</izz>
          </inertia>
        </inertial>
        <collision name='bottom'>
          <pose frame=''>0 -0.1 0.01 0 -0 0</pose>
          <geometry>
            <box>
              <size>0.5 0.35 0.02</size>
            </box>
          </geometry>
          <max_contacts>10</max_contacts>
          <surface>
            <contact>
              <ode/>
            </contact>
            <bounce/>
            <friction>
              <torsional>
                <ode/>
              </torsional>
              <ode/>
            </friction>
          </surface>
        </collision>
        <collision name='person'>
          <pose frame=''>0 0 0.02 0.04 -0 0</pose>
          <geometry>
            <mesh>
              <uri>model://person_standing/meshes/standing.dae</uri>
            </mesh>
          </geometry>
          <max_contacts>10</max_contacts>
          <surface>
            <contact>
              <ode/>
            </contact>
            <bounce/>
            <friction>
              <torsional>
                <ode/>
              </torsional>
              <ode/>
            </friction>
          </surface>
        </collision>
        <visual name='visual'>
          <pose frame=''>0 0 0.02 0.04 -0 0</pose>
          <geometry>
            <mesh>
              <uri>model://person_standing/meshes/standing.dae</uri>
            </mesh>
          </geometry>
        </visual>
        <self_collide>0</self_collide>
        <enable_wind>0</enable_wind>
        <kinematic>0</kinematic>
      </link>
      <pose frame=''>-13.296 -0.195515 0 0 -0 0</pose>
    </model>
    <model name='person_walking'>
      <link name='link'>
        <inertial>
          <pose frame=''>0 0 0.95 0 -0 0</pose>
          <mass>80</mass>
          <inertia>
            <ixx>27.82</ixx>
            <ixy>0</ixy>
            <ixz>0</ixz>
            <iyy>24.88</iyy>
            <iyz>0</iyz>
            <izz>4.57</izz>
          </inertia>
        </inertial>
        <collision name='bottom'>
          <pose frame=''>0 0 0.01 0 -0 0</pose>
          <geometry>
            <box>
              <size>0.35 0.75 0.02</size>
            </box>
          </geometry>
          <max_contacts>10</max_contacts>
          <surface>
            <contact>
              <ode/>
            </contact>
            <bounce/>
            <friction>
              <torsional>
                <ode/>
              </torsional>
              <ode/>
            </friction>
          </surface>
        </collision>
        <collision name='person'>
          <pose frame=''>0 0 -0.02 0 -0 0</pose>
          <geometry>
            <mesh>
              <uri>model://person_walking/meshes/walking.dae</uri>
            </mesh>
          </geometry>
          <max_contacts>10</max_contacts>
          <surface>
            <contact>
              <ode/>
            </contact>
            <bounce/>
            <friction>
              <torsional>
                <ode/>
              </torsional>
              <ode/>
            </friction>
          </surface>
        </collision>
        <visual name='visual'>
          <pose frame=''>0 0 -0.02 0 -0 0</pose>
          <geometry>
            <mesh>
              <uri>model://person_walking/meshes/walking.dae</uri>
            </mesh>
          </geometry>
        </visual>
        <self_collide>0</self_collide>
        <enable_wind>0</enable_wind>
        <kinematic>0</kinematic>
      </link>
      <pose frame=''>4.30741 4.78948 0 0 -0 0</pose>
    </model>
    <model name='person_standing_1'>
      <link name='link'>
        <inertial>
          <pose frame=''>0 -0.1 0.95 0 -0 0</pose>
          <mass>80</mass>
          <inertia>
            <ixx>24.88</ixx>
            <ixy>0</ixy>
            <ixz>0</ixz>
            <iyy>25.73</iyy>
            <iyz>0</iyz>
            <izz>2.48</izz>
          </inertia>
        </inertial>
        <collision name='bottom'>
          <pose frame=''>0 -0.1 0.01 0 -0 0</pose>
          <geometry>
            <box>
              <size>0.5 0.35 0.02</size>
            </box>
          </geometry>
          <max_contacts>10</max_contacts>
          <surface>
            <contact>
              <ode/>
            </contact>
            <bounce/>
            <friction>
              <torsional>
                <ode/>
              </torsional>
              <ode/>
            </friction>
          </surface>
        </collision>
        <collision name='person'>
          <pose frame=''>0 0 0.02 0.04 -0 0</pose>
          <geometry>
            <mesh>
              <uri>model://person_standing/meshes/standing.dae</uri>
            </mesh>
          </geometry>
          <max_contacts>10</max_contacts>
          <surface>
            <contact>
              <ode/>
            </contact>
            <bounce/>
            <friction>
              <torsional>
                <ode/>
              </torsional>
              <ode/>
            </friction>
          </surface>
        </collision>
        <visual name='visual'>
          <pose frame=''>0 0 0.02 0.04 -0 0</pose>
          <geometry>
            <mesh>
              <uri>model://person_standing/meshes/standing.dae</uri>
            </mesh>
          </geometry>
        </visual>
        <self_collide>0</self_collide>
        <enable_wind>0</enable_wind>
        <kinematic>0</kinematic>
      </link>
      <pose frame=''>12.9642 0.110974 0 0 -0 0</pose>
    </model>
    <model name='soccer_ball'>
      <static>0</static>
      <link name='soccer_ball_link'>
        <pose frame=''>0 0 0 0 -0 0</pose>
        <inertial>
          <mass>0.026</mass>
          <inertia>
            <ixx>1.664e-05</ixx>
            <iyy>1.664e-05</iyy>
            <izz>1.664e-05</izz>
            <ixy>0</ixy>
            <ixz>0</ixz>
            <iyz>0</iyz>
          </inertia>
          <pose frame=''>0 0 0 0 -0 0</pose>
        </inertial>
        <collision name='collision'>
          <geometry>
            <sphere>
              <radius>0.04</radius>
            </sphere>
          </geometry>
          <max_contacts>10</max_contacts>
          <surface>
            <contact>
              <ode/>
            </contact>
            <bounce/>
            <friction>
              <torsional>
                <ode/>
              </torsional>
              <ode/>
            </friction>
          </surface>
        </collision>
        <visual name='visual'>
          <geometry>
            <mesh>
              <scale>0.04 0.04 0.04</scale>
              <uri>model://robocup_3Dsim_ball/meshes/ball.dae</uri>
            </mesh>
          </geometry>
        </visual>
        <self_collide>0</self_collide>
        <enable_wind>0</enable_wind>
        <kinematic>0</kinematic>
      </link>
      <pose frame=''>-0.611099 0.154681 0 0 -0 0</pose>
    </model>
    <model name='nist'>
      <static>1</static>
      <link name='nist_maze_wall_triple_holes_120_link'>
        <pose frame=''>0 0 0 0 -0 0</pose>
        <collision name='collision'>
          <geometry>
            <mesh>
              <uri>model://nist_maze_wall_triple_holes_120/meshes/nist_maze_wall_triple_holes_120.dae</uri>
              <scale>1 1 1</scale>
            </mesh>
          </geometry>
          <max_contacts>10</max_contacts>
          <surface>
            <contact>
              <ode/>
            </contact>
            <bounce/>
            <friction>
              <torsional>
                <ode/>
              </torsional>
              <ode/>
            </friction>
          </surface>
        </collision>
        <visual name='visual'>
          <geometry>
            <mesh>
              <uri>model://nist_maze_wall_triple_holes_120/meshes/nist_maze_wall_triple_holes_120.dae</uri>
              <scale>1 1 1</scale>
            </mesh>
          </geometry>
        </visual>
        <self_collide>0</self_collide>
        <enable_wind>0</enable_wind>
        <kinematic>0</kinematic>
      </link>
      <pose frame=''>-7.02178 -10.3171 0 0 -0 0</pose>
    </model>
    <model name='nist_maze_wall_120'>
      <static>1</static>
      <link name='nist_maze_wall_120_link'>
        <pose frame=''>0 0 0 0 -0 0</pose>
        <collision name='collision'>
          <geometry>
            <mesh>
              <uri>model://nist_maze_wall_120/meshes/nist_maze_wall_120.dae</uri>
              <scale>1 1 1</scale>
            </mesh>
          </geometry>
          <max_contacts>10</max_contacts>
          <surface>
            <contact>
              <ode/>
            </contact>
            <bounce/>
            <friction>
              <torsional>
                <ode/>
              </torsional>
              <ode/>
            </friction>
          </surface>
        </collision>
        <visual name='visual'>
          <geometry>
            <mesh>
              <uri>model://nist_maze_wall_120/meshes/nist_maze_wall_120.dae</uri>
              <scale>1 1 1</scale>
            </mesh>
          </geometry>
        </visual>
        <self_collide>0</self_collide>
        <enable_wind>0</enable_wind>
        <kinematic>0</kinematic>
      </link>
      <pose frame=''>-6.03742 -10.3019 0 0 -0 0</pose>
    </model>
    <model name='nist_stairs_120'>
      <static>1</static>
      <link name='nist_stairs_120_link'>
        <pose frame=''>0 0 0 0 -0 0</pose>
        <collision name='collision'>
          <geometry>
            <mesh>
              <uri>model://nist_stairs_120/meshes/nist_stairs_120.dae</uri>
              <scale>1 1 1</scale>
            </mesh>
          </geometry>
          <max_contacts>10</max_contacts>
          <surface>
            <contact>
              <ode/>
            </contact>
            <bounce/>
            <friction>
              <torsional>
                <ode/>
              </torsional>
              <ode/>
            </friction>
          </surface>
        </collision>
        <visual name='visual'>
          <geometry>
            <mesh>
              <uri>model://nist_stairs_120/meshes/nist_stairs_120.dae</uri>
              <scale>1 1 1</scale>
            </mesh>
          </geometry>
        </visual>
        <self_collide>0</self_collide>
        <enable_wind>0</enable_wind>
        <kinematic>0</kinematic>
      </link>
      <pose frame=''>-6.60525 -10.3181 0 0 -0 0</pose>
    </model>
    <model name='warehouse_robot'>
      <static>1</static>
      <link name='link'>
        <visual name='visual'>
          <geometry>
            <mesh>
              <uri>model://warehouse_robot/meshes/robot.dae</uri>
            </mesh>
          </geometry>
        </visual>
        <collision name='collision_base'>
          <pose frame=''>0 0 0.20437 0 -0 0</pose>
          <geometry>
            <box>
              <size>0.55508 1.0228 0.40874</size>
            </box>
          </geometry>
          <max_contacts>10</max_contacts>
          <surface>
            <contact>
              <ode/>
            </contact>
            <bounce/>
            <friction>
              <torsional>
                <ode/>
              </torsional>
              <ode/>
            </friction>
          </surface>
        </collision>
        <collision name='collision_bumper'>
          <pose frame=''>0 0 0.062205 0 -0 0</pose>
          <geometry>
            <box>
              <size>0.67266 1.17126 0.12441</size>
            </box>
          </geometry>
          <max_contacts>10</max_contacts>
          <surface>
            <contact>
              <ode/>
            </contact>
            <bounce/>
            <friction>
              <torsional>
                <ode/>
              </torsional>
              <ode/>
            </friction>
          </surface>
        </collision>
        <collision name='collision_column_large'>
          <pose frame=''>0 -0.27539 0.43738 0 -0 0</pose>
          <geometry>
            <cylinder>
              <radius>0.08652</radius>
              <length>0.87476</length>
            </cylinder>
          </geometry>
          <max_contacts>10</max_contacts>
          <surface>
            <contact>
              <ode/>
            </contact>
            <bounce/>
            <friction>
              <torsional>
                <ode/>
              </torsional>
              <ode/>
            </friction>
          </surface>
        </collision>
        <collision name='collision_column_small'>
          <pose frame=''>0 -0.27539 0.70424 0 -0 0</pose>
          <geometry>
            <cylinder>
              <radius>0.04261</radius>
              <length>1.40848</length>
            </cylinder>
          </geometry>
          <max_contacts>10</max_contacts>
          <surface>
            <contact>
              <ode/>
            </contact>
            <bounce/>
            <friction>
              <torsional>
                <ode/>
              </torsional>
              <ode/>
            </friction>
          </surface>
        </collision>
        <self_collide>0</self_collide>
        <enable_wind>0</enable_wind>
        <kinematic>0</kinematic>
      </link>
      <pose frame=''>4.89501 -10.8887 0 0 -0 0</pose>
    </model>
    <model name='grey_wall'>
      <static>1</static>
      <link name='link'>
        <pose frame=''>0 0 1.4 0 -0 0</pose>
        <collision name='collision'>
          <geometry>
            <box>
              <size>7.5 0.2 2.8</size>
            </box>
          </geometry>
          <max_contacts>10</max_contacts>
          <surface>
            <contact>
              <ode/>
            </contact>
            <bounce/>
            <friction>
              <torsional>
                <ode/>
              </torsional>
              <ode/>
            </friction>
          </surface>
        </collision>
        <visual name='visual'>
          <cast_shadows>0</cast_shadows>
          <geometry>
            <box>
              <size>7.5 0.2 2.8</size>
            </box>
          </geometry>
          <material>
            <script>
              <uri>model://grey_wall/materials/scripts</uri>
              <uri>model://grey_wall/materials/textures</uri>
              <name>vrc/grey_wall</name>
            </script>
          </material>
        </visual>
        <self_collide>0</self_collide>
        <enable_wind>0</enable_wind>
        <kinematic>0</kinematic>
      </link>
      <pose frame=''>9.22771 12.1917 0 0 -0 0</pose>
    </model>
    <model name='frc2016_drawbridge'>
      <link name='base'>
        <inertial>
          <mass>10</mass>
          <pose frame=''>0 0 1 0 -0 0</pose>
          <inertia>
            <ixx>3.64907</ixx>
            <ixy>0</ixy>
            <ixz>0</ixz>
            <iyy>4.67075</iyy>
            <iyz>0</iyz>
            <izz>1.66649</izz>
          </inertia>
        </inertial>
        <visual name='platform'>
          <pose frame=''>0 0 0.0425 0 -0 0</pose>
          <geometry>
            <box>
              <size>1.27 0.5969 0.085</size>
            </box>
          </geometry>
        </visual>
        <collision name='platform'>
          <pose frame=''>0 0 0.0425 0 -0 0</pose>
          <geometry>
            <box>
              <size>1.27 0.5969 0.085</size>
            </box>
          </geometry>
          <max_contacts>10</max_contacts>
          <surface>
            <contact>
              <ode/>
            </contact>
            <bounce/>
            <friction>
              <torsional>
                <ode/>
              </torsional>
              <ode/>
            </friction>
          </surface>
        </collision>
        <visual name='right_wall'>
          <pose frame=''>0.55879 0.04444 0.889 0 -0 0</pose>
          <geometry>
            <box>
              <size>0.05715 0.45698 1.77165</size>
            </box>
          </geometry>
        </visual>
        <collision name='right_wall'>
          <pose frame=''>0.55879 0.04444 0.889 0 -0 0</pose>
          <geometry>
            <box>
              <size>0.05715 0.45698 1.77165</size>
            </box>
          </geometry>
          <max_contacts>10</max_contacts>
          <surface>
            <contact>
              <ode/>
            </contact>
            <bounce/>
            <friction>
              <torsional>
                <ode/>
              </torsional>
              <ode/>
            </friction>
          </surface>
        </collision>
        <visual name='left_wall'>
          <pose frame=''>-0.55879 0.04444 0.889 0 -0 0</pose>
          <geometry>
            <box>
              <size>0.05715 0.45698 1.77165</size>
            </box>
          </geometry>
        </visual>
        <collision name='left_wall'>
          <pose frame=''>-0.55879 0.04444 0.889 0 -0 0</pose>
          <geometry>
            <box>
              <size>0.05715 0.45698 1.77165</size>
            </box>
          </geometry>
          <max_contacts>10</max_contacts>
          <surface>
            <contact>
              <ode/>
            </contact>
            <bounce/>
            <friction>
              <torsional>
                <ode/>
              </torsional>
              <ode/>
            </friction>
          </surface>
        </collision>
        <visual name='front_upper_wall'>
          <pose frame=''>0 0.27611 1.84286 0 -0 0</pose>
          <geometry>
            <box>
              <size>1.1557 0.006347 0.254</size>
            </box>
          </geometry>
        </visual>
        <collision name='front_upper_wall'>
          <pose frame=''>0 0.27611 1.84286 0 -0 0</pose>
          <geometry>
            <box>
              <size>1.1557 0.006347 0.254</size>
            </box>
          </geometry>
          <max_contacts>10</max_contacts>
          <surface>
            <contact>
              <ode/>
            </contact>
            <bounce/>
            <friction>
              <torsional>
                <ode/>
              </torsional>
              <ode/>
            </friction>
          </surface>
        </collision>
        <visual name='back_upper_wall'>
          <pose frame=''>0 -0.18722 1.84286 0 -0 0</pose>
          <geometry>
            <box>
              <size>1.1557 0.006347 0.254</size>
            </box>
          </geometry>
        </visual>
        <collision name='back_upper_wall'>
          <pose frame=''>0 -0.18722 1.84286 0 -0 0</pose>
          <geometry>
            <box>
              <size>1.1557 0.006347 0.254</size>
            </box>
          </geometry>
          <max_contacts>10</max_contacts>
          <surface>
            <contact>
              <ode/>
            </contact>
            <bounce/>
            <friction>
              <torsional>
                <ode/>
              </torsional>
              <ode/>
            </friction>
          </surface>
        </collision>
        <self_collide>0</self_collide>
        <enable_wind>0</enable_wind>
        <kinematic>0</kinematic>
      </link>
      <link name='bridge'>
        <pose frame=''>0 0.28245 0.50577 0 -0 0</pose>
        <inertial>
          <mass>2</mass>
          <pose frame=''>0 -0.28245 -0.50577 0 -0 0</pose>
          <inertia>
            <ixx>0.139361</ixx>
            <ixy>0</ixy>
            <ixz>0</ixz>
            <iyy>0.357088</iyy>
            <iyz>0</iyz>
            <izz>0.217741</izz>
          </inertia>
        </inertial>
        <visual name='visual'>
          <geometry>
            <box>
              <size>1.14298 0.006347 0.9144</size>
            </box>
          </geometry>
          <material>
            <script>
              <name>Gazebo/WoodFloor</name>
              <uri>__default__</uri>
            </script>
          </material>
        </visual>
        <collision name='collision'>
          <geometry>
            <box>
              <size>1.14298 0.006347 0.9144</size>
            </box>
          </geometry>
          <max_contacts>10</max_contacts>
          <surface>
            <contact>
              <ode/>
            </contact>
            <bounce/>
            <friction>
              <torsional>
                <ode/>
              </torsional>
              <ode/>
            </friction>
          </surface>
        </collision>
        <self_collide>0</self_collide>
        <enable_wind>0</enable_wind>
        <kinematic>0</kinematic>
      </link>
      <joint name='bridge_joint' type='revolute'>
        <pose frame=''>0 0 -0.4172 0 -0 0</pose>
        <parent>base</parent>
        <child>bridge</child>
        <axis>
          <xyz>1 0 0</xyz>
          <limit>
            <lower>-2</lower>
            <upper>0</upper>
          </limit>
          <use_parent_model_frame>0</use_parent_model_frame>
          <dynamics>
            <spring_reference>0</spring_reference>
            <spring_stiffness>0</spring_stiffness>
          </dynamics>
        </axis>
      </joint>
      <pose frame=''>10.3493 -9.94412 0 0 -0 0</pose>
    </model>
    <model name='first_2015_trash_can'>
      <link name='link'>
        <inertial>
          <pose frame=''>0 0 0.3683 0 -0 0</pose>
          <mass>4.83076</mass>
          <inertia>
            <ixx>0.281534</ixx>
            <ixy>0</ixy>
            <ixz>0</ixz>
            <iyy>0.281534</iyy>
            <iyz>0</iyz>
            <izz>0.126223</izz>
          </inertia>
        </inertial>
        <visual name='visual'>
          <geometry>
            <mesh>
              <uri>model://first_2015_trash_can/meshes/trash_can.dae</uri>
            </mesh>
          </geometry>
        </visual>
        <collision name='collision'>
          <geometry>
            <mesh>
              <uri>model://first_2015_trash_can/meshes/trash_can.dae</uri>
            </mesh>
          </geometry>
          <max_contacts>10</max_contacts>
          <surface>
            <contact>
              <ode/>
            </contact>
            <bounce/>
            <friction>
              <torsional>
                <ode/>
              </torsional>
              <ode/>
            </friction>
          </surface>
        </collision>
        <self_collide>0</self_collide>
        <enable_wind>0</enable_wind>
        <kinematic>0</kinematic>
      </link>
      <pose frame=''>10.4974 -10.8687 0 0 -0 0</pose>
    </model>
    <model name='Construction Cone'>
      <link name='link'>
        <collision name='collision'>
          <geometry>
            <mesh>
              <scale>10 10 10</scale>
              <uri>model://construction_cone/meshes/construction_cone.dae</uri>
            </mesh>
          </geometry>
          <max_contacts>10</max_contacts>
          <surface>
            <contact>
              <ode/>
            </contact>
            <bounce/>
            <friction>
              <torsional>
                <ode/>
              </torsional>
              <ode/>
            </friction>
          </surface>
        </collision>
        <visual name='visual'>
          <geometry>
            <mesh>
              <scale>10 10 10</scale>
              <uri>model://construction_cone/meshes/construction_cone.dae</uri>
            </mesh>
          </geometry>
        </visual>
        <self_collide>0</self_collide>
        <inertial>
          <pose frame=''>0 0 0 0 -0 0</pose>
          <inertia>
            <ixx>1</ixx>
            <ixy>0</ixy>
            <ixz>0</ixz>
            <iyy>1</iyy>
            <iyz>0</iyz>
            <izz>1</izz>
          </inertia>
          <mass>1</mass>
        </inertial>
        <enable_wind>0</enable_wind>
        <kinematic>0</kinematic>
      </link>
      <pose frame=''>-5.80047 11.3933 0 0 -0 0</pose>
    </model>
    <model name='wood_slats'>
      <static>1</static>
      <link name='link'>
        <collision name='collision'>
          <geometry>
            <mesh>
              <uri>model://drc_practice_wood_slats/meshes/wood_slats.dae</uri>
            </mesh>
          </geometry>
          <surface>
            <bounce>
              <restitution_coefficient>0.01</restitution_coefficient>
              <threshold>5</threshold>
            </bounce>
            <friction>
              <ode>
                <mu>5</mu>
                <mu2>5</mu2>
              </ode>
              <torsional>
                <ode/>
              </torsional>
            </friction>
            <contact>
              <ode>
                <soft_cfm>0.001</soft_cfm>
                <kp>10000</kp>
                <kd>1000</kd>
                <max_vel>0.01</max_vel>
                <min_depth>0.001</min_depth>
              </ode>
            </contact>
          </surface>
          <max_contacts>10</max_contacts>
        </collision>
        <visual name='visual'>
          <geometry>
            <mesh>
              <uri>model://drc_practice_wood_slats/meshes/wood_slats.dae</uri>
            </mesh>
          </geometry>
        </visual>
        <self_collide>0</self_collide>
        <enable_wind>0</enable_wind>
        <kinematic>0</kinematic>
      </link>
      <pose frame=''>-1.0343 -4.34552 0 0 -0 0</pose>
    </model>
    <model name='cessna_c172'>
      <pose frame=''>-14.4243 11.0006 0.495 0 -0 0</pose>
      <link name='body'>
        <inertial>
          <mass>680.389</mass>
          <inertia>
            <ixx>1285.32</ixx>
            <ixy>0</ixy>
            <iyy>1824.93</iyy>
            <ixz>0</ixz>
            <iyz>0</iyz>
            <izz>2666.89</izz>
          </inertia>
          <pose frame=''>-0.0414 0 0.9271 0 -0 0</pose>
        </inertial>
        <collision name='collision'>
          <geometry>
            <mesh>
              <uri>model://cessna/meshes/body.dae</uri>
            </mesh>
          </geometry>
          <max_contacts>10</max_contacts>
          <surface>
            <contact>
              <ode/>
            </contact>
            <bounce/>
            <friction>
              <torsional>
                <ode/>
              </torsional>
              <ode/>
            </friction>
          </surface>
        </collision>
        <visual name='visual'>
          <geometry>
            <mesh>
              <uri>model://cessna/meshes/body.dae</uri>
            </mesh>
          </geometry>
        </visual>
        <visual name='cp_left_wing'>
          <pose frame=''>-1 2.205 1.5 0 -0 0</pose>
          <geometry>
            <sphere>
              <radius>0.1</radius>
            </sphere>
          </geometry>
        </visual>
        <visual name='cp_right_wing'>
          <pose frame=''>-1 -2.205 1.5 0 -0 0</pose>
          <geometry>
            <sphere>
              <radius>0.1</radius>
            </sphere>
          </geometry>
        </visual>
        <visual name='cp_elevator'>
          <pose frame=''>-5.45 0 0.55 0 -0 0</pose>
          <geometry>
            <sphere>
              <radius>0.1</radius>
            </sphere>
          </geometry>
        </visual>
        <visual name='cp_rudder'>
          <pose frame=''>-6 0 1.55 0 -0 0</pose>
          <geometry>
            <sphere>
              <radius>0.1</radius>
            </sphere>
          </geometry>
        </visual>
        <self_collide>0</self_collide>
        <enable_wind>0</enable_wind>
        <kinematic>0</kinematic>
      </link>
      <link name='left_aileron'>
        <inertial>
          <mass>2</mass>
          <inertia>
            <ixx>0.8434</ixx>
            <ixy>0</ixy>
            <iyy>0.0119</iyy>
            <ixz>0</ixz>
            <iyz>0</iyz>
            <izz>0.855</izz>
          </inertia>
          <pose frame=''>-1.65 3.7 1.5 0.05 -0 -0.12</pose>
        </inertial>
        <collision name='collision'>
          <geometry>
            <mesh>
              <uri>model://cessna/meshes/left_aileron.dae</uri>
            </mesh>
          </geometry>
          <max_contacts>10</max_contacts>
          <surface>
            <contact>
              <ode/>
            </contact>
            <bounce/>
            <friction>
              <torsional>
                <ode/>
              </torsional>
              <ode/>
            </friction>
          </surface>
        </collision>
        <visual name='visual'>
          <geometry>
            <mesh>
              <uri>model://cessna/meshes/left_aileron.dae</uri>
            </mesh>
          </geometry>
        </visual>
        <self_collide>0</self_collide>
        <enable_wind>0</enable_wind>
        <kinematic>0</kinematic>
      </link>
      <link name='left_flap'>
        <inertial>
          <mass>2</mass>
          <inertia>
            <ixx>0.6747</ixx>
            <ixy>0</ixy>
            <iyy>0.0242</iyy>
            <ixz>0</ixz>
            <iyz>0</iyz>
            <izz>0.6962</izz>
          </inertia>
          <pose frame=''>-1.8 1.55 1.43 0.02 -0 0</pose>
        </inertial>
        <collision name='collision'>
          <geometry>
            <mesh>
              <uri>model://cessna/meshes/left_flap.dae</uri>
            </mesh>
          </geometry>
          <max_contacts>10</max_contacts>
          <surface>
            <contact>
              <ode/>
            </contact>
            <bounce/>
            <friction>
              <torsional>
                <ode/>
              </torsional>
              <ode/>
            </friction>
          </surface>
        </collision>
        <visual name='visual'>
          <geometry>
            <mesh>
              <uri>model://cessna/meshes/left_flap.dae</uri>
            </mesh>
          </geometry>
        </visual>
        <self_collide>0</self_collide>
        <enable_wind>0</enable_wind>
        <kinematic>0</kinematic>
      </link>
      <link name='right_aileron'>
        <inertial>
          <mass>2</mass>
          <inertia>
            <ixx>0.8434</ixx>
            <ixy>0</ixy>
            <iyy>0.0119</iyy>
            <ixz>0</ixz>
            <iyz>0</iyz>
            <izz>0.855</izz>
          </inertia>
          <pose frame=''>-1.65 -3.7 1.5 -0.05 -0 0.12</pose>
        </inertial>
        <collision name='collision'>
          <geometry>
            <mesh>
              <uri>model://cessna/meshes/right_aileron.dae</uri>
            </mesh>
          </geometry>
          <max_contacts>10</max_contacts>
          <surface>
            <contact>
              <ode/>
            </contact>
            <bounce/>
            <friction>
              <torsional>
                <ode/>
              </torsional>
              <ode/>
            </friction>
          </surface>
        </collision>
        <visual name='visual'>
          <geometry>
            <mesh>
              <uri>model://cessna/meshes/right_aileron.dae</uri>
            </mesh>
          </geometry>
        </visual>
        <self_collide>0</self_collide>
        <enable_wind>0</enable_wind>
        <kinematic>0</kinematic>
      </link>
      <link name='right_flap'>
        <inertial>
          <mass>2</mass>
          <inertia>
            <ixx>0.6747</ixx>
            <ixy>0</ixy>
            <iyy>0.0242</iyy>
            <ixz>0</ixz>
            <iyz>0</iyz>
            <izz>0.6962</izz>
          </inertia>
          <pose frame=''>-1.8 -1.55 1.43 -0.02 0 0</pose>
        </inertial>
        <collision name='collision'>
          <geometry>
            <mesh>
              <uri>model://cessna/meshes/right_flap.dae</uri>
            </mesh>
          </geometry>
          <max_contacts>10</max_contacts>
          <surface>
            <contact>
              <ode/>
            </contact>
            <bounce/>
            <friction>
              <torsional>
                <ode/>
              </torsional>
              <ode/>
            </friction>
          </surface>
        </collision>
        <visual name='visual'>
          <geometry>
            <mesh>
              <uri>model://cessna/meshes/right_flap.dae</uri>
            </mesh>
          </geometry>
        </visual>
        <self_collide>0</self_collide>
        <enable_wind>0</enable_wind>
        <kinematic>0</kinematic>
      </link>
      <link name='elevators'>
        <inertial>
          <mass>2</mass>
          <inertia>
            <ixx>1.5008</ixx>
            <ixy>0</ixy>
            <iyy>0.0274</iyy>
            <ixz>0</ixz>
            <iyz>0</iyz>
            <izz>1.5266</izz>
          </inertia>
          <pose frame=''>-5.75 0 0.57 0 -0 0</pose>
        </inertial>
        <collision name='collision'>
          <geometry>
            <mesh>
              <uri>model://cessna/meshes/elevators.dae</uri>
            </mesh>
          </geometry>
          <max_contacts>10</max_contacts>
          <surface>
            <contact>
              <ode/>
            </contact>
            <bounce/>
            <friction>
              <torsional>
                <ode/>
              </torsional>
              <ode/>
            </friction>
          </surface>
        </collision>
        <visual name='visual'>
          <geometry>
            <mesh>
              <uri>model://cessna/meshes/elevators.dae</uri>
            </mesh>
          </geometry>
        </visual>
        <self_collide>0</self_collide>
        <enable_wind>0</enable_wind>
        <kinematic>0</kinematic>
      </link>
      <link name='rudder'>
        <inertial>
          <mass>2</mass>
          <inertia>
            <ixx>0.4708</ixx>
            <ixy>0</ixy>
            <iyy>0.5208</iyy>
            <ixz>0</ixz>
            <iyz>0</iyz>
            <izz>0.0508</izz>
          </inertia>
          <pose frame=''>-6.1 0 1.3 0 -0.35 0</pose>
        </inertial>
        <collision name='collision'>
          <geometry>
            <mesh>
              <uri>model://cessna/meshes/rudder.dae</uri>
            </mesh>
          </geometry>
          <max_contacts>10</max_contacts>
          <surface>
            <contact>
              <ode/>
            </contact>
            <bounce/>
            <friction>
              <torsional>
                <ode/>
              </torsional>
              <ode/>
            </friction>
          </surface>
        </collision>
        <visual name='visual'>
          <geometry>
            <mesh>
              <uri>model://cessna/meshes/rudder.dae</uri>
            </mesh>
          </geometry>
        </visual>
        <self_collide>0</self_collide>
        <enable_wind>0</enable_wind>
        <kinematic>0</kinematic>
      </link>
      <link name='propeller'>
        <pose frame=''>1.79 0 0.855 0 -0 0</pose>
        <inertial>
          <mass>18.37</mass>
          <inertia>
            <ixx>7.5067</ixx>
            <ixy>0</ixy>
            <iyy>7.515</iyy>
            <ixz>0</ixz>
            <iyz>0</iyz>
            <izz>0.068275</izz>
          </inertia>
          <pose frame=''>-0.35 0 0 0 -0 0</pose>
        </inertial>
        <collision name='collision'>
          <geometry>
            <mesh>
              <uri>model://cessna/meshes/cessna_prop.dae</uri>
            </mesh>
          </geometry>
          <max_contacts>10</max_contacts>
          <surface>
            <contact>
              <ode/>
            </contact>
            <bounce/>
            <friction>
              <torsional>
                <ode/>
              </torsional>
              <ode/>
            </friction>
          </surface>
        </collision>
        <visual name='visual'>
          <geometry>
            <mesh>
              <uri>model://cessna/meshes/cessna_prop.dae</uri>
            </mesh>
          </geometry>
        </visual>
        <visual name='prop_cp'>
          <pose frame=''>-0.37 0 0.77 0 -0 0</pose>
          <geometry>
            <sphere>
              <radius>0.2</radius>
            </sphere>
          </geometry>
        </visual>
        <self_collide>0</self_collide>
        <enable_wind>0</enable_wind>
        <kinematic>0</kinematic>
      </link>
      <link name='front_wheel'>
        <inertial>
          <mass>2</mass>
          <inertia>
            <ixx>0.01786</ixx>
            <ixy>0</ixy>
            <iyy>0.01786</iyy>
            <ixz>0</ixz>
            <iyz>0</iyz>
            <izz>0.0324</izz>
          </inertia>
          <pose frame=''>0.712 0 -0.313 1.57079 -0 0</pose>
        </inertial>
        <collision name='collision'>
          <pose frame=''>0.712 0 -0.313 1.57079 -0 0</pose>
          <geometry>
            <cylinder>
              <radius>0.18</radius>
              <length>0.1</length>
            </cylinder>
          </geometry>
          <surface>
            <friction>
              <ode>
                <mu>0.3</mu>
                <mu2>0.3</mu2>
              </ode>
              <torsional>
                <ode/>
              </torsional>
            </friction>
            <contact>
              <ode>
                <max_vel>0.1</max_vel>
                <min_depth>0.001</min_depth>
              </ode>
            </contact>
            <bounce/>
          </surface>
          <max_contacts>10</max_contacts>
        </collision>
        <visual name='visual'>
          <geometry>
            <mesh>
              <uri>model://cessna/meshes/cessna_front_wheel.dae</uri>
            </mesh>
          </geometry>
        </visual>
        <self_collide>0</self_collide>
        <enable_wind>0</enable_wind>
        <kinematic>0</kinematic>
      </link>
      <link name='rear_left_wheel'>
        <inertial>
          <mass>2</mass>
          <inertia>
            <ixx>0.035516</ixx>
            <ixy>0</ixy>
            <iyy>0.035516</iyy>
            <ixz>0</ixz>
            <iyz>0</iyz>
            <izz>0.0625</izz>
          </inertia>
          <pose frame=''>-1 1.27 -0.25 1.57079 -0 0</pose>
        </inertial>
        <collision name='collision'>
          <pose frame=''>-1 1.27 -0.25 1.57079 -0 0</pose>
          <geometry>
            <cylinder>
              <radius>0.25</radius>
              <length>0.16</length>
            </cylinder>
          </geometry>
          <surface>
            <friction>
              <ode>
                <mu>0.3</mu>
                <mu2>0.3</mu2>
              </ode>
              <torsional>
                <ode/>
              </torsional>
            </friction>
            <contact>
              <ode>
                <max_vel>0.1</max_vel>
                <min_depth>0.001</min_depth>
              </ode>
            </contact>
            <bounce/>
          </surface>
          <max_contacts>10</max_contacts>
        </collision>
        <visual name='visual'>
          <geometry>
            <mesh>
              <uri>model://cessna/meshes/cessna_rear_left_wheel.dae</uri>
            </mesh>
          </geometry>
        </visual>
        <self_collide>0</self_collide>
        <enable_wind>0</enable_wind>
        <kinematic>0</kinematic>
      </link>
      <link name='rear_right_wheel'>
        <inertial>
          <mass>2</mass>
          <inertia>
            <ixx>0.035516</ixx>
            <ixy>0</ixy>
            <iyy>0.035516</iyy>
            <ixz>0</ixz>
            <iyz>0</iyz>
            <izz>0.0625</izz>
          </inertia>
          <pose frame=''>-1 -1.27 -0.25 1.57079 -0 0</pose>
        </inertial>
        <collision name='collision'>
          <pose frame=''>-1 -1.27 -0.25 1.57079 -0 0</pose>
          <geometry>
            <cylinder>
              <radius>0.25</radius>
              <length>0.16</length>
            </cylinder>
          </geometry>
          <surface>
            <friction>
              <ode>
                <mu>0.3</mu>
                <mu2>0.3</mu2>
              </ode>
              <torsional>
                <ode/>
              </torsional>
            </friction>
            <contact>
              <ode>
                <max_vel>0.1</max_vel>
                <min_depth>0.001</min_depth>
              </ode>
            </contact>
            <bounce/>
          </surface>
          <max_contacts>10</max_contacts>
        </collision>
        <visual name='visual'>
          <geometry>
            <mesh>
              <uri>model://cessna/meshes/cessna_rear_right_wheel.dae</uri>
            </mesh>
          </geometry>
        </visual>
        <self_collide>0</self_collide>
        <enable_wind>0</enable_wind>
        <kinematic>0</kinematic>
      </link>
      <joint name='left_flap_joint' type='revolute'>
        <parent>body</parent>
        <child>left_flap</child>
        <pose frame=''>-1.6 1.55 1.43 0.02 -0 0</pose>
        <axis>
          <xyz>0 1 0</xyz>
          <limit>
            <lower>-0.53</lower>
            <upper>0.53</upper>
            <effort>-1</effort>
            <velocity>-1</velocity>
          </limit>
          <dynamics>
            <damping>1</damping>
            <spring_reference>0</spring_reference>
            <spring_stiffness>0</spring_stiffness>
          </dynamics>
          <use_parent_model_frame>0</use_parent_model_frame>
        </axis>
        <physics>
          <ode>
            <implicit_spring_damper>1</implicit_spring_damper>
            <limit>
              <cfm>0</cfm>
              <erp>0.2</erp>
            </limit>
          </ode>
        </physics>
      </joint>
      <joint name='left_aileron_joint' type='revolute'>
        <parent>body</parent>
        <child>left_aileron</child>
        <pose frame=''>-1.45 3.7 1.5 0.05 -0 -0.12</pose>
        <axis>
          <xyz>0 1 0</xyz>
          <limit>
            <lower>-0.53</lower>
            <upper>0.53</upper>
            <effort>-1</effort>
            <velocity>-1</velocity>
          </limit>
          <dynamics>
            <damping>1</damping>
            <spring_reference>0</spring_reference>
            <spring_stiffness>0</spring_stiffness>
          </dynamics>
          <use_parent_model_frame>0</use_parent_model_frame>
        </axis>
        <physics>
          <ode>
            <implicit_spring_damper>1</implicit_spring_damper>
            <limit>
              <cfm>0</cfm>
              <erp>0.2</erp>
            </limit>
          </ode>
        </physics>
      </joint>
      <joint name='right_flap_joint' type='revolute'>
        <parent>body</parent>
        <child>right_flap</child>
        <pose frame=''>-1.6 -1.55 1.43 -0.02 0 0</pose>
        <axis>
          <xyz>0 1 0</xyz>
          <limit>
            <lower>-0.53</lower>
            <upper>0.53</upper>
            <effort>-1</effort>
            <velocity>-1</velocity>
          </limit>
          <dynamics>
            <damping>1</damping>
            <spring_reference>0</spring_reference>
            <spring_stiffness>0</spring_stiffness>
          </dynamics>
          <use_parent_model_frame>0</use_parent_model_frame>
        </axis>
        <physics>
          <ode>
            <implicit_spring_damper>1</implicit_spring_damper>
            <limit>
              <cfm>0</cfm>
              <erp>0.2</erp>
            </limit>
          </ode>
        </physics>
      </joint>
      <joint name='right_aileron_joint' type='revolute'>
        <parent>body</parent>
        <child>right_aileron</child>
        <pose frame=''>-1.45 -3.7 1.5 -0.05 -0 0.12</pose>
        <axis>
          <xyz>0 1 0</xyz>
          <limit>
            <lower>-0.53</lower>
            <upper>0.53</upper>
            <effort>-1</effort>
            <velocity>-1</velocity>
          </limit>
          <dynamics>
            <damping>1</damping>
            <spring_reference>0</spring_reference>
            <spring_stiffness>0</spring_stiffness>
          </dynamics>
          <use_parent_model_frame>0</use_parent_model_frame>
        </axis>
        <physics>
          <ode>
            <implicit_spring_damper>1</implicit_spring_damper>
            <limit>
              <cfm>0</cfm>
              <erp>0.2</erp>
            </limit>
          </ode>
        </physics>
      </joint>
      <joint name='elevators_joint' type='revolute'>
        <parent>body</parent>
        <child>elevators</child>
        <pose frame=''>-5.55 0 0.57 0 -0 0</pose>
        <axis>
          <xyz>0 1 0</xyz>
          <limit>
            <lower>-0.53</lower>
            <upper>0.53</upper>
            <effort>-1</effort>
            <velocity>-1</velocity>
          </limit>
          <dynamics>
            <damping>1</damping>
            <spring_reference>0</spring_reference>
            <spring_stiffness>0</spring_stiffness>
          </dynamics>
          <use_parent_model_frame>0</use_parent_model_frame>
        </axis>
        <physics>
          <ode>
            <implicit_spring_damper>1</implicit_spring_damper>
            <limit>
              <cfm>0</cfm>
              <erp>0.2</erp>
            </limit>
          </ode>
        </physics>
      </joint>
      <joint name='rudder_joint' type='revolute'>
        <parent>body</parent>
        <child>rudder</child>
        <pose frame=''>-5.9 0 1.3 0 -0.35 0</pose>
        <axis>
          <xyz>0 0 1</xyz>
          <limit>
            <lower>-0.53</lower>
            <upper>0.53</upper>
            <effort>-1</effort>
            <velocity>-1</velocity>
          </limit>
          <dynamics>
            <damping>1</damping>
            <spring_reference>0</spring_reference>
            <spring_stiffness>0</spring_stiffness>
          </dynamics>
          <use_parent_model_frame>0</use_parent_model_frame>
        </axis>
        <physics>
          <ode>
            <implicit_spring_damper>1</implicit_spring_damper>
            <limit>
              <cfm>0</cfm>
              <erp>0.2</erp>
            </limit>
          </ode>
        </physics>
      </joint>
      <joint name='propeller_joint' type='revolute'>
        <parent>body</parent>
        <child>propeller</child>
        <axis>
          <xyz>1 0 0</xyz>
          <limit>
            <lower>-1e+12</lower>
            <upper>1e+12</upper>
            <effort>-1</effort>
            <velocity>-1</velocity>
          </limit>
          <dynamics>
            <damping>0.001</damping>
            <spring_reference>0</spring_reference>
            <spring_stiffness>0</spring_stiffness>
          </dynamics>
          <use_parent_model_frame>0</use_parent_model_frame>
        </axis>
        <physics>
          <ode>
            <implicit_spring_damper>1</implicit_spring_damper>
            <limit>
              <cfm>0</cfm>
              <erp>0.2</erp>
            </limit>
          </ode>
        </physics>
      </joint>
      <joint name='front_wheel_joint' type='revolute'>
        <parent>body</parent>
        <child>front_wheel</child>
        <pose frame=''>0.712 0 -0.313 0 -0 0</pose>
        <axis>
          <xyz>0 1 0</xyz>
          <limit>
            <lower>-1e+12</lower>
            <upper>1e+12</upper>
            <effort>-1</effort>
            <velocity>-1</velocity>
          </limit>
          <dynamics>
            <damping>0.01</damping>
            <spring_reference>0</spring_reference>
            <spring_stiffness>0</spring_stiffness>
          </dynamics>
          <use_parent_model_frame>0</use_parent_model_frame>
        </axis>
        <physics>
          <ode>
            <implicit_spring_damper>1</implicit_spring_damper>
            <limit>
              <cfm>0</cfm>
              <erp>0.2</erp>
            </limit>
          </ode>
        </physics>
      </joint>
      <joint name='rear_left_wheel_joint' type='revolute'>
        <parent>body</parent>
        <child>rear_left_wheel</child>
        <pose frame=''>-1 -1.27 -0.25 0 -0 0</pose>
        <axis>
          <xyz>0 1 0</xyz>
          <limit>
            <lower>-1e+12</lower>
            <upper>1e+12</upper>
            <effort>-1</effort>
            <velocity>-1</velocity>
          </limit>
          <dynamics>
            <damping>0.01</damping>
            <spring_reference>0</spring_reference>
            <spring_stiffness>0</spring_stiffness>
          </dynamics>
          <use_parent_model_frame>0</use_parent_model_frame>
        </axis>
        <physics>
          <ode>
            <implicit_spring_damper>1</implicit_spring_damper>
            <limit>
              <cfm>0</cfm>
              <erp>0.2</erp>
            </limit>
          </ode>
        </physics>
      </joint>
      <joint name='rear_right_wheel_joint' type='revolute'>
        <parent>body</parent>
        <child>rear_right_wheel</child>
        <pose frame=''>-1 1.27 -0.25 0 -0 0</pose>
        <axis>
          <xyz>0 1 0</xyz>
          <limit>
            <lower>-1e+12</lower>
            <upper>1e+12</upper>
            <effort>-1</effort>
            <velocity>-1</velocity>
          </limit>
          <dynamics>
            <damping>0.01</damping>
            <spring_reference>0</spring_reference>
            <spring_stiffness>0</spring_stiffness>
          </dynamics>
          <use_parent_model_frame>0</use_parent_model_frame>
        </axis>
        <physics>
          <ode>
            <implicit_spring_damper>1</implicit_spring_damper>
            <limit>
              <cfm>0</cfm>
              <erp>0.2</erp>
            </limit>
          </ode>
        </physics>
      </joint>
    </model>
    <model name='cardboard_box'>
      <pose frame=''>4.10023 -0.868372 0.15 0 -0 0</pose>
      <link name='link'>
        <inertial>
          <mass>2</mass>
          <inertia>
            <ixx>0.0416667</ixx>
            <ixy>0</ixy>
            <ixz>0</ixz>
            <iyy>0.0566667</iyy>
            <iyz>0</iyz>
            <izz>0.0683333</izz>
          </inertia>
          <pose frame=''>0 0 0 0 -0 0</pose>
        </inertial>
        <collision name='collision'>
          <geometry>
            <box>
              <size>0.5 0.4 0.3</size>
            </box>
          </geometry>
          <surface>
            <friction>
              <ode>
                <mu>1</mu>
                <mu2>1</mu2>
              </ode>
              <torsional>
                <ode/>
              </torsional>
            </friction>
            <contact>
              <ode>
                <kp>1e+07</kp>
                <kd>1</kd>
                <min_depth>0.001</min_depth>
                <max_vel>0.1</max_vel>
              </ode>
            </contact>
            <bounce/>
          </surface>
          <max_contacts>10</max_contacts>
        </collision>
        <visual name='visual'>
          <pose frame=''>0 0 -0.15 0 -0 0</pose>
          <geometry>
            <mesh>
              <uri>model://cardboard_box/meshes/cardboard_box.dae</uri>
              <scale>1.25932 1.00745 0.755591</scale>
            </mesh>
          </geometry>
        </visual>
        <self_collide>0</self_collide>
        <enable_wind>0</enable_wind>
        <kinematic>0</kinematic>
      </link>
    </model>
    <state world_name='default'>
      <sim_time>367 765000000</sim_time>
      <real_time>561 463535695</real_time>
      <wall_time>1587810031 315730736</wall_time>
      <iterations>367765</iterations>
      <model name='Construction Cone'>
        <pose frame=''>-5.80047 11.3933 0.01 1e-06 -1e-06 0</pose>
        <scale>1 1 1</scale>
        <link name='link'>
          <pose frame=''>-5.80047 11.3933 0.01 1e-06 -1e-06 0</pose>
          <velocity>0 0 0 0 -0 0</velocity>
          <acceleration>-1e-06 -0 -1.80334 -1.78072 -1.13075 -3.14159</acceleration>
          <wrench>-1e-06 -0 -1.80334 0 -0 0</wrench>
        </link>
      </model>
      <model name='RoboCup 2014 SPL Goal'>
        <pose frame=''>14.2398 -0.350873 0 0 -0 0</pose>
        <scale>1 1 1</scale>
        <link name='center_net'>
          <pose frame=''>14.6798 -0.350873 0.4 0 -0 0</pose>
          <velocity>0 0 0 0 -0 0</velocity>
          <acceleration>0 0 0 0 -0 0</acceleration>
          <wrench>0 0 0 0 -0 0</wrench>
        </link>
        <link name='center_support_horiz_lower'>
          <pose frame=''>14.6798 -0.350873 0.01 3.14159 1.57079 3.14159</pose>
          <velocity>0 0 0 0 -0 0</velocity>
          <acceleration>0 0 0 0 -0 0</acceleration>
          <wrench>0 0 0 0 -0 0</wrench>
        </link>
        <link name='center_support_horiz_upper'>
          <pose frame=''>14.6798 -0.350873 0.79 3.14159 1.57079 3.14159</pose>
          <velocity>0 0 0 0 -0 0</velocity>
          <acceleration>0 0 0 0 -0 0</acceleration>
          <wrench>0 0 0 0 -0 0</wrench>
        </link>
        <link name='crossbar'>
          <pose frame=''>14.2398 -0.350873 0.85 1.57 1.57 0</pose>
          <velocity>0 0 0 0 -0 0</velocity>
          <acceleration>0 0 0 0 -0 0</acceleration>
          <wrench>0 0 0 0 -0 0</wrench>
        </link>
        <link name='left_net'>
          <pose frame=''>14.4798 0.449127 0.4 0 -0 0</pose>
          <velocity>0 0 0 0 -0 0</velocity>
          <acceleration>0 0 0 0 -0 0</acceleration>
          <wrench>0 0 0 0 -0 0</wrench>
        </link>
        <link name='left_post'>
          <pose frame=''>14.2398 0.449127 0.45 0 -0 0</pose>
          <velocity>0 0 0 0 -0 0</velocity>
          <acceleration>0 0 0 0 -0 0</acceleration>
          <wrench>0 0 0 0 -0 0</wrench>
        </link>
        <link name='left_support_horiz_lower'>
          <pose frame=''>14.4798 0.449127 0.01 0 -0 0</pose>
          <velocity>0 0 0 0 -0 0</velocity>
          <acceleration>0 0 0 0 -0 0</acceleration>
          <wrench>0 0 0 0 -0 0</wrench>
        </link>
        <link name='left_support_horiz_upper'>
          <pose frame=''>14.4798 0.449127 0.79 0 -0 0</pose>
          <velocity>0 0 0 0 -0 0</velocity>
          <acceleration>0 0 0 0 -0 0</acceleration>
          <wrench>0 0 0 0 -0 0</wrench>
        </link>
        <link name='left_support_vertical'>
          <pose frame=''>14.6798 0.449127 0.4 3.14159 1.57079 3.14159</pose>
          <velocity>0 0 0 0 -0 0</velocity>
          <acceleration>0 0 0 0 -0 0</acceleration>
          <wrench>0 0 0 0 -0 0</wrench>
        </link>
        <link name='right_net'>
          <pose frame=''>14.4798 -1.15087 0.4 0 -0 0</pose>
          <velocity>0 0 0 0 -0 0</velocity>
          <acceleration>0 0 0 0 -0 0</acceleration>
          <wrench>0 0 0 0 -0 0</wrench>
        </link>
        <link name='right_post'>
          <pose frame=''>14.2398 -1.15087 0.45 0 -0 0</pose>
          <velocity>0 0 0 0 -0 0</velocity>
          <acceleration>0 0 0 0 -0 0</acceleration>
          <wrench>0 0 0 0 -0 0</wrench>
        </link>
        <link name='right_support_horiz_lower'>
          <pose frame=''>14.4798 -1.15087 0.01 0 -0 0</pose>
          <velocity>0 0 0 0 -0 0</velocity>
          <acceleration>0 0 0 0 -0 0</acceleration>
          <wrench>0 0 0 0 -0 0</wrench>
        </link>
        <link name='right_support_horiz_upper'>
          <pose frame=''>14.4798 -1.15087 0.79 0 -0 0</pose>
          <velocity>0 0 0 0 -0 0</velocity>
          <acceleration>0 0 0 0 -0 0</acceleration>
          <wrench>0 0 0 0 -0 0</wrench>
        </link>
        <link name='right_support_vertical'>
          <pose frame=''>14.6798 -1.15087 0.4 3.14159 1.57079 3.14159</pose>
          <velocity>0 0 0 0 -0 0</velocity>
          <acceleration>0 0 0 0 -0 0</acceleration>
          <wrench>0 0 0 0 -0 0</wrench>
        </link>
      </model>
      <model name='cardboard_box'>
        <pose frame=''>4.10023 -0.868372 0.159 -0 -0 -0</pose>
        <scale>1 1 1</scale>
        <link name='link'>
          <pose frame=''>4.10023 -0.868372 0.159 -0 -0 -0</pose>
          <velocity>0 0 0 0 -0 0</velocity>
          <acceleration>-0 -2e-06 0 1.1e-05 -0 0</acceleration>
          <wrench>-0 -3e-06 0 0 -0 0</wrench>
        </link>
      </model>
      <model name='cessna_c172'>
        <pose frame=''>-13.7543 10.8072 0.457099 -0.006632 -0.066673 -0.205738</pose>
        <scale>1 1 1</scale>
        <link name='body'>
          <pose frame=''>-13.7543 10.8072 0.457099 -0.006632 -0.066673 -0.205738</pose>
          <velocity>0.016591 -0.009364 -0.132783 0.016122 0.04509 -0.002382</velocity>
          <acceleration>-0.024737 -0.139777 -9.36419 0.231363 0.06892 0.034687</acceleration>
          <wrench>-16.8308 -95.1028 -6371.29 0 -0 0</wrench>
        </link>
        <link name='elevators'>
          <pose frame=''>-14.4017 10.9619 3.30478 -0.008002 -0.597024 -0.201681</pose>
          <velocity>0.394226 -0.108956 -0.564972 0.035844 0.139416 -0.003022</velocity>
          <acceleration>0.313854 -0.200549 -9.2721 0.834788 -0.699384 -3.0299</acceleration>
          <wrench>0.627707 -0.401099 -18.5442 0 -0 0</wrench>
        </link>
        <link name='front_wheel'>
          <pose frame=''>-13.1619 10.6764 -0.575454 -3.11518 -1.31749 2.90985</pose>
          <velocity>-0.634673 0.132948 -0.061341 0.180826 0.832609 -0.007718</velocity>
          <acceleration>-0.11746 0.176746 -9.46717 0.21018 -0.313064 0.044937</acceleration>
          <wrench>-0.234921 0.353492 -18.9343 0 -0 0</wrench>
        </link>
        <link name='left_aileron'>
          <pose frame=''>-13.4566 10.6451 1.61491 -0.069278 -0.593245 -0.212564</pose>
          <velocity>0.069088 -0.016508 -0.366113 0.047775 0.139809 0.002745</velocity>
          <acceleration>-0.10399 -0.247939 -8.32633 -1.86594 0.031189 -2.9474</acceleration>
          <wrench>-0.20798 -0.495879 -16.6527 0 -0 0</wrench>
        </link>
        <link name='left_flap'>
          <pose frame=''>-13.346 10.7083 1.48893 -0.003871 -0.597053 -0.213915</pose>
          <velocity>0.038359 -0.018999 -0.357825 0.036462 0.14299 -0.001049</velocity>
          <acceleration>-0.040731 -0.250686 -8.80882 0.519462 1.35543 0.051035</acceleration>
          <wrench>-0.081461 -0.501372 -17.6176 0 -0 0</wrench>
        </link>
        <link name='propeller'>
          <pose frame=''>-12.0606 10.4596 1.42944 0.173112 -0.066675 -0.205738</pose>
          <velocity>0.059609 -0.029354 -0.213401 -0.000999 0.050293 -0.003572</velocity>
          <acceleration>-0.01841 -0.054139 -9.56519 0.196586 0.37463 -1.76893</acceleration>
          <wrench>-0.338188 -0.994529 -175.713 0 -0 0</wrench>
        </link>
        <link name='rear_left_wheel'>
          <pose frame=''>-15.5033 11.1738 0.907445 -3.13413 -0.917798 2.92948</pose>
          <velocity>0.306947 0.115133 0.450475 -0.023494 0.345973 -0.003418</velocity>
          <acceleration>-1.82296 0.392045 -2.10639 -0.191784 -1.17337 0.154769</acceleration>
          <wrench>-3.64593 0.784089 -4.21279 0 -0 0</wrench>
        </link>
        <link name='rear_right_wheel'>
          <pose frame=''>-14.8531 11.03 -0.767737 -3.12911 1.1891 2.947</pose>
          <velocity>-1.09712 0.253309 0.311369 0.1499 1.17319 -0.008343</velocity>
          <acceleration>-0.385994 0.199856 -8.85313 0.20476 -0.242433 0.279493</acceleration>
          <wrench>-0.771989 0.399713 -17.7063 0 -0 0</wrench>
        </link>
        <link name='right_aileron'>
          <pose frame=''>-13.4134 10.8516 1.61506 0.053399 -0.593771 -0.190875</pose>
          <velocity>0.048917 -0.088586 -1.08815 0.053037 0.455678 -0.028997</velocity>
          <acceleration>1.39676 -0.550742 -7.78062 0.376728 -0.155457 -1.87285</acceleration>
          <wrench>2.79351 -1.10149 -15.5612 0 -0 0</wrench>
        </link>
        <link name='right_flap'>
          <pose frame=''>-13.3377 10.7476 1.48937 -0.012138 -0.597225 -0.189436</pose>
          <velocity>0.036869 -0.027235 -0.358425 0.036694 0.142915 -0.00504</velocity>
          <acceleration>-0.086169 -0.239655 -9.11111 0.524744 1.36758 5e-05</acceleration>
          <wrench>-0.172338 -0.479311 -18.2222 0 -0 0</wrench>
        </link>
        <link name='rudder'>
          <pose frame=''>-13.7062 11.068 0.452551 -0.027727 -0.065833 -0.156745</pose>
          <velocity>-0.510585 -3.30869 -0.037574 0.275158 -0.013181 -0.602127</velocity>
          <acceleration>-0.061157 -1.13917 -8.52903 -1.9379 0.880954 -2.07477</acceleration>
          <wrench>-0.122314 -2.27834 -17.0581 0 -0 0</wrench>
        </link>
      </model>
      <model name='first_2015_trash_can'>
        <pose frame=''>10.4975 -10.8687 0.009998 1e-06 1.1e-05 -0.00043</pose>
        <scale>1 1 1</scale>
        <link name='link'>
          <pose frame=''>10.4975 -10.8687 0.009998 1e-06 1.1e-05 -0.00043</pose>
          <velocity>0 0 0 0 -0 0</velocity>
          <acceleration>5.40607 -0.777268 3.09623 -1.03167 1.02941 -3.1411</acceleration>
          <wrench>26.1154 -3.7548 14.9572 0 -0 0</wrench>
        </link>
      </model>
      <model name='frc2016_drawbridge'>
        <pose frame=''>10.3493 -9.94412 0.01 0 -0 -1e-06</pose>
        <scale>1 1 1</scale>
        <link name='base'>
          <pose frame=''>10.3493 -9.94412 0.01 0 -0 -1e-06</pose>
          <velocity>0 -0 -0 0 -0 0</velocity>
          <acceleration>-2e-06 -0.000112 -1.8e-05 0.000112 -2e-06 -0</acceleration>
          <wrench>-1.7e-05 -0.001119 -0.000184 0 -0 0</wrench>
        </link>
        <link name='bridge'>
          <pose frame=''>10.3493 -9.66167 0.51577 2e-06 0 -1e-06</pose>
          <velocity>0 0.006607 0 -0.015837 0 0</velocity>
          <acceleration>-3e-06 -2.96129 9.4433 -2.01763 3.8e-05 0</acceleration>
          <wrench>-5e-06 -5.92258 18.8866 0 -0 0</wrench>
        </link>
      </model>
      <model name='grey_wall'>
        <pose frame=''>9.22771 12.1917 0 0 -0 0</pose>
        <scale>1 1 1</scale>
        <link name='link'>
          <pose frame=''>9.22771 12.1917 1.4 0 -0 0</pose>
          <velocity>0 0 0 0 -0 0</velocity>
          <acceleration>0 0 0 0 -0 0</acceleration>
          <wrench>0 0 0 0 -0 0</wrench>
        </link>
      </model>
      <model name='ground_plane'>
        <pose frame=''>0 0 0 0 -0 0</pose>
        <scale>1 1 1</scale>
        <link name='link'>
          <pose frame=''>0 0 0 0 -0 0</pose>
          <velocity>0 0 0 0 -0 0</velocity>
          <acceleration>0 0 0 0 -0 0</acceleration>
          <wrench>0 0 0 0 -0 0</wrench>
        </link>
      </model>
      <model name='iris'>
        <pose frame=''>2.6e-05 0.000113 0.009603 -0.002019 -0 7.4e-05</pose>
        <scale>1 1 1</scale>
        <link name='camera'>
          <pose frame=''>-0.019957 -0.009722 0.099638 -0.000792 0.000427 1.57167</pose>
          <velocity>-6.5e-05 2.4e-05 9e-06 0.000247 0.000125 -5.3e-05</velocity>
          <acceleration>-0.140579 0.049224 0.014016 0.252884 0.113404 -0.063952</acceleration>
          <wrench>-0.014058 0.004922 0.001402 0 -0 0</wrench>
        </link>
        <link name='iris_demo::cam_link'>
          <pose frame=''>2.6e-05 0.000113 0.009603 -0.002019 -0 7.4e-05</pose>
          <velocity>-2.8e-05 7e-06 2e-06 -2.2e-05 8.8e-05 -3e-05</velocity>
          <acceleration>-0.058138 0.014581 0.003356 -0.013808 0.022137 -0.062809</acceleration>
          <wrench>-0.000581 0.000146 3.4e-05 0 -0 0</wrench>
        </link>
        <link name='iris_demo::gimbal_small_2d::base_link'>
          <pose frame=''>2.7e-05 -0.009745 0.079623 1.57 -0.002019 -1.56993</pose>
          <velocity>-1.8e-05 8e-06 2e-06 -2.2e-05 8.8e-05 -0.000104</velocity>
          <acceleration>-0.048877 0.013346 0.003495 -0.01395 0.021641 -0.166248</acceleration>
          <wrench>-0.009775 0.002669 0.000699 0 -0 0</wrench>
        </link>
        <link name='iris_demo::gimbal_small_2d::tilt_link'>
          <pose frame=''>-0.019957 -0.009722 0.099638 3.14079 -0.002019 -1.56993</pose>
          <velocity>-3.2e-05 1.1e-05 4e-06 -2.2e-05 0.000423 -0.000125</velocity>
          <acceleration>-0.077511 0.021411 0.004998 -0.022291 0.570567 -0.211084</acceleration>
          <wrench>-0.000775 0.000214 5e-05 0 -0 0</wrench>
        </link>
        <link name='iris_demo::iris::base_link'>
          <pose frame=''>2.6e-05 0.000507 0.204525 -0.002019 -0 7.4e-05</pose>
          <velocity>-0 9e-06 2e-06 -4.6e-05 -2e-06 0</velocity>
          <acceleration>-0.032316 0.012219 0.002953 -0.064151 -0.162706 -0.001182</acceleration>
          <wrench>-0.048474 0.018328 0.00443 0 -0 0</wrench>
        </link>
        <link name='iris_demo::iris::iris/ground_truth/odometry_sensorgt_link'>
          <pose frame=''>2.6e-05 0.000507 0.204525 -0.002019 -0 7.4e-05</pose>
          <velocity>-7e-06 1e-05 2e-06 -2.3e-05 8.7e-05 -2.2e-05</velocity>
          <acceleration>-0.046246 0.015415 0.00344 -0.016218 0.020747 -0.049354</acceleration>
          <wrench>-0.006937 0.002312 0.000516 0 -0 0</wrench>
        </link>
        <link name='iris_demo::iris::iris/imu_link'>
          <pose frame=''>2.6e-05 0.000507 0.204525 -0.002019 -0 7.4e-05</pose>
          <velocity>-7e-06 1e-05 2e-06 -2.3e-05 8.8e-05 -2.2e-05</velocity>
          <acceleration>-0.045928 0.015282 0.003408 -0.016173 0.020818 -0.04934</acceleration>
          <wrench>-0.006889 0.002292 0.000511 0 -0 0</wrench>
        </link>
        <link name='iris_demo::iris::rotor_0'>
          <pose frame=''>0.130042 -0.219436 0.227969 -0.002019 3e-06 0.001286</pose>
          <velocity>-1.2e-05 7e-06 -4e-06 -2.3e-05 8.8e-05 8e-06</velocity>
          <acceleration>-0.059186 0.007206 0.004221 -0.015737 0.02091 -0.000257</acceleration>
          <wrench>-0.00148 0.00018 0.000106 0 -0 0</wrench>
        </link>
        <link name='iris_demo::iris::rotor_1'>
          <pose frame=''>-0.129989 0.200543 0.227121 -0.002019 2e-06 0.001239</pose>
          <velocity>1e-06 1.5e-05 9e-06 -2.2e-05 8.8e-05 8e-06</velocity>
          <acceleration>-0.032574 0.023608 0.003165 -0.014428 0.021509 -0.000256</acceleration>
          <wrench>-0.000814 0.00059 7.9e-05 0 -0 0</wrench>
        </link>
        <link name='iris_demo::iris::rotor_2'>
          <pose frame=''>0.13001 0.220563 0.227081 -0.002019 3e-06 0.001278</pose>
          <velocity>2e-06 7e-06 -1.4e-05 -2.2e-05 8.8e-05 8e-06</velocity>
          <acceleration>-0.031054 0.007208 -0.002568 -0.013608 0.021905 -0.00026</acceleration>
          <wrench>-0.000776 0.00018 -6.4e-05 0 -0 0</wrench>
        </link>
        <link name='iris_demo::iris::rotor_3'>
          <pose frame=''>-0.129959 -0.199456 0.227929 -0.002019 3e-06 0.001281</pose>
          <velocity>-1.1e-05 1.5e-05 1.8e-05 -2.2e-05 8.8e-05 8e-06</velocity>
          <acceleration>-0.057725 0.023765 0.009056 -0.013688 0.022118 -0.000266</acceleration>
          <wrench>-0.001443 0.000594 0.000226 0 -0 0</wrench>
        </link>
      </model>
      <model name='nist'>
        <pose frame=''>-7.02178 -10.3171 0 0 -0 0</pose>
        <scale>1 1 1</scale>
        <link name='nist_maze_wall_triple_holes_120_link'>
          <pose frame=''>-7.02178 -10.3171 0 0 -0 0</pose>
          <velocity>0 0 0 0 -0 0</velocity>
          <acceleration>0 0 0 0 -0 0</acceleration>
          <wrench>0 0 0 0 -0 0</wrench>
        </link>
      </model>
      <model name='nist_maze_wall_120'>
        <pose frame=''>-6.03742 -10.3019 0 0 -0 0</pose>
        <scale>1 1 1</scale>
        <link name='nist_maze_wall_120_link'>
          <pose frame=''>-6.03742 -10.3019 0 0 -0 0</pose>
          <velocity>0 0 0 0 -0 0</velocity>
          <acceleration>0 0 0 0 -0 0</acceleration>
          <wrench>0 0 0 0 -0 0</wrench>
        </link>
      </model>
      <model name='nist_stairs_120'>
        <pose frame=''>-6.60525 -10.3181 0 0 -0 0</pose>
        <scale>1 1 1</scale>
        <link name='nist_stairs_120_link'>
          <pose frame=''>-6.60525 -10.3181 0 0 -0 0</pose>
          <velocity>0 0 0 0 -0 0</velocity>
          <acceleration>0 0 0 0 -0 0</acceleration>
          <wrench>0 0 0 0 -0 0</wrench>
        </link>
      </model>
      <model name='person_standing'>
        <pose frame=''>-4.22798 -6.53934 0.01 0 -0 0.838824</pose>
        <scale>1 1 1</scale>
        <link name='link'>
          <pose frame=''>-4.22798 -6.53934 0.01 0 -0 0.838824</pose>
          <velocity>0 0 0 0 -0 0</velocity>
          <acceleration>0.038013 -0.00045 0 0.001127 0.040759 0</acceleration>
          <wrench>3.04103 -0.03601 0 0 -0 0</wrench>
        </link>
      </model>
      <model name='person_standing_0'>
        <pose frame=''>-13.296 -0.195699 0.01 1e-06 -0 1.62806</pose>
        <scale>1 1 1</scale>
        <link name='link'>
          <pose frame=''>-13.296 -0.195699 0.01 1e-06 -0 1.62806</pose>
          <velocity>0 0 0 0 -0 0</velocity>
          <acceleration>1.2723 0.08047 -0.494768 -0.083893 1.38504 0.002343</acceleration>
          <wrench>101.784 6.4376 -39.5814 0 -0 0</wrench>
        </link>
      </model>
      <model name='person_standing_1'>
        <pose frame=''>12.9642 0.110903 0.01 1e-06 -0 -1.56771</pose>
        <scale>1 1 1</scale>
        <link name='link'>
          <pose frame=''>12.9642 0.110903 0.01 1e-06 -0 -1.56771</pose>
          <velocity>0 0 0 0 -0 0</velocity>
          <acceleration>-1.27487 0.003505 -0.494486 -0.002781 -1.38781 -0.002365</acceleration>
          <wrench>-101.99 0.280361 -39.5589 0 -0 0</wrench>
        </link>
      </model>
      <model name='person_walking'>
        <pose frame=''>4.30741 4.78948 0.01 0 -0 -0.586209</pose>
        <scale>1 1 1</scale>
        <link name='link'>
          <pose frame=''>4.30741 4.78948 0.01 0 -0 -0.586209</pose>
          <velocity>0 0 0 0 -0 0</velocity>
          <acceleration>-0.001084 0.000571 -0 -0.000678 -0.001137 -0</acceleration>
          <wrench>-0.086703 0.045665 -0 0 -0 0</wrench>
        </link>
      </model>
      <model name='robocup_3d_field'>
        <pose frame=''>-0.280458 0.370204 0 0 -0 0</pose>
        <scale>1 1 1</scale>
        <link name='field'>
          <pose frame=''>-0.280458 0.370204 0.01 0 -0 0</pose>
          <velocity>0 0 0 0 -0 0</velocity>
          <acceleration>0 0 0 0 -0 0</acceleration>
          <wrench>0 0 0 0 -0 0</wrench>
        </link>
      </model>
      <model name='robocup_3d_goal'>
        <pose frame=''>-15.1906 0.117807 0 0 -0 0.036898</pose>
        <scale>1 1 1</scale>
        <link name='center_net'>
          <pose frame=''>-14.631 0.138465 0.4 0 -0 0.036898</pose>
          <velocity>0 0 0 0 -0 0</velocity>
          <acceleration>0 0 0 0 -0 0</acceleration>
          <wrench>0 0 0 0 -0 0</wrench>
        </link>
        <link name='center_support_horiz_lower'>
          <pose frame=''>-14.631 0.138465 0.01 3.14159 1.57079 -3.1047</pose>
          <velocity>0 0 0 0 -0 0</velocity>
          <acceleration>0 0 0 0 -0 0</acceleration>
          <wrench>0 0 0 0 -0 0</wrench>
        </link>
        <link name='center_support_horiz_upper'>
          <pose frame=''>-14.631 0.138465 0.79 3.14159 1.57079 -3.1047</pose>
          <velocity>0 0 0 0 -0 0</velocity>
          <acceleration>0 0 0 0 -0 0</acceleration>
          <wrench>0 0 0 0 -0 0</wrench>
        </link>
        <link name='crossbar'>
          <pose frame=''>-15.1906 0.117807 0.85 1.57 1.57 0.036898</pose>
          <velocity>0 0 0 0 -0 0</velocity>
          <acceleration>0 0 0 0 -0 0</acceleration>
          <wrench>0 0 0 0 -0 0</wrench>
        </link>
        <link name='left_net'>
          <pose frame=''>-14.9296 1.17816 0.4 0 -0 0.036898</pose>
          <velocity>0 0 0 0 -0 0</velocity>
          <acceleration>0 0 0 0 -0 0</acceleration>
          <wrench>0 0 0 0 -0 0</wrench>
        </link>
        <link name='left_post'>
          <pose frame=''>-15.2294 1.16709 0.45 0 -0 0.036898</pose>
          <velocity>0 0 0 0 -0 0</velocity>
          <acceleration>0 0 0 0 -0 0</acceleration>
          <wrench>0 0 0 0 -0 0</wrench>
        </link>
        <link name='left_support_horiz_lower'>
          <pose frame=''>-14.9296 1.17816 0.01 0 -0 0.036898</pose>
          <velocity>0 0 0 0 -0 0</velocity>
          <acceleration>0 0 0 0 -0 0</acceleration>
          <wrench>0 0 0 0 -0 0</wrench>
        </link>
        <link name='left_support_horiz_upper'>
          <pose frame=''>-14.9296 1.17816 0.79 0 -0 0.036898</pose>
          <velocity>0 0 0 0 -0 0</velocity>
          <acceleration>0 0 0 0 -0 0</acceleration>
          <wrench>0 0 0 0 -0 0</wrench>
        </link>
        <link name='left_support_vertical'>
          <pose frame=''>-14.6697 1.18775 0.4 3.14159 1.57079 -3.1047</pose>
          <velocity>0 0 0 0 -0 0</velocity>
          <acceleration>0 0 0 0 -0 0</acceleration>
          <wrench>0 0 0 0 -0 0</wrench>
        </link>
        <link name='right_net'>
          <pose frame=''>-14.8521 -0.920411 0.4 0 -0 0.036898</pose>
          <velocity>0 0 0 0 -0 0</velocity>
          <acceleration>0 0 0 0 -0 0</acceleration>
          <wrench>0 0 0 0 -0 0</wrench>
        </link>
        <link name='right_post'>
          <pose frame=''>-15.1519 -0.931478 0.45 0 -0 0.036898</pose>
          <velocity>0 0 0 0 -0 0</velocity>
          <acceleration>0 0 0 0 -0 0</acceleration>
          <wrench>0 0 0 0 -0 0</wrench>
        </link>
        <link name='right_support_horiz_lower'>
          <pose frame=''>-14.8521 -0.920411 0.01 0 -0 0.036898</pose>
          <velocity>0 0 0 0 -0 0</velocity>
          <acceleration>0 0 0 0 -0 0</acceleration>
          <wrench>0 0 0 0 -0 0</wrench>
        </link>
        <link name='right_support_horiz_upper'>
          <pose frame=''>-14.8521 -0.920411 0.79 0 -0 0.036898</pose>
          <velocity>0 0 0 0 -0 0</velocity>
          <acceleration>0 0 0 0 -0 0</acceleration>
          <wrench>0 0 0 0 -0 0</wrench>
        </link>
        <link name='right_support_vertical'>
          <pose frame=''>-14.5923 -0.91082 0.4 3.14159 1.57079 -3.1047</pose>
          <velocity>0 0 0 0 -0 0</velocity>
          <acceleration>0 0 0 0 -0 0</acceleration>
          <wrench>0 0 0 0 -0 0</wrench>
        </link>
      </model>
      <model name='soccer_ball'>
        <pose frame=''>-0.611099 0.154681 0.05 0 -0 0</pose>
        <scale>1 1 1</scale>
        <link name='soccer_ball_link'>
          <pose frame=''>-0.611099 0.154681 0.05 0 -0 0</pose>
          <velocity>0 0 0 0 -0 0</velocity>
          <acceleration>0 0 0 0 -0 0</acceleration>
          <wrench>0 0 0 0 -0 0</wrench>
        </link>
      </model>
      <model name='warehouse_robot'>
        <pose frame=''>4.89501 -10.8887 0 0 -0 0</pose>
        <scale>1 1 1</scale>
        <link name='link'>
          <pose frame=''>4.89501 -10.8887 0 0 -0 0</pose>
          <velocity>0 0 0 0 -0 0</velocity>
          <acceleration>0 0 0 0 -0 0</acceleration>
          <wrench>0 0 0 0 -0 0</wrench>
        </link>
      </model>
      <model name='wood_slats'>
        <pose frame=''>-1.0343 -4.34552 0 0 -0 0</pose>
        <scale>1 1 1</scale>
        <link name='link'>
          <pose frame=''>-1.0343 -4.34552 0 0 -0 0</pose>
          <velocity>0 0 0 0 -0 0</velocity>
          <acceleration>0 0 0 0 -0 0</acceleration>
          <wrench>0 0 0 0 -0 0</wrench>
        </link>
      </model>
      <light name='sun'>
        <pose frame=''>0 0 10 0 -0 0</pose>
      </light>
    </state>
    <gui fullscreen='0'>
      <camera name='user_camera'>
        <pose frame=''>27.7232 -28.0427 13.0555 0 0.275643 2.35619</pose>
        <view_controller>orbit</view_controller>
        <projection_type>perspective</projection_type>
      </camera>
    </gui>
  </world>
</sdf>
